2016-07-22 16:09:19,777 - __main__ - DEBUG - there is a error
Traceback (most recent call last):
  File "spyder.py", line 39, in spyder
    cur.execute("insert into People_Inf values(?, ?, ?)", (Title_Section[0], Description[0], people, parent, level))
OperationalError: table People_Inf has 5 columns but 3 values were supplied
2016-07-22 16:20:52,576 - __main__ - DEBUG - there is a error
Traceback (most recent call last):
  File "spyder.py", line 40, in spyder
    cur.execute("insert into People_Inf values(?, ?, ?)", (Title_Section[0], Description[0], people, parent, level))
OperationalError: table People_Inf has 5 columns but 3 values were supplied
2016-07-22 16:21:52,900 - __main__ - DEBUG - there is a error
Traceback (most recent call last):
  File "spyder.py", line 40, in spyder
    cur.execute("insert into People_Inf values(?, ?, ?)", (Title_Section[0], Description[0], people, parent, level))
OperationalError: table People_Inf has 5 columns but 3 values were supplied
2016-07-22 16:23:25,000 - __main__ - DEBUG - there is a error
Traceback (most recent call last):
  File "spyder.py", line 40, in spyder
    cur.execute("insert into People_Inf values(?, ?, ?)", (Title_Section[0], Description[0], people, parent, level))
OperationalError: table People_Inf has 5 columns but 3 values were supplied
