2016-07-25 16:52:06,906 - __main__ - DEBUG - there is a error
Traceback (most recent call last):
  File "spyder.py", line 26, in spyder
    MyResponse = urllib2.urlopen(req)
  File "/usr/local/lib/python2.7/urllib2.py", line 154, in urlopen
    return opener.open(url, data, timeout)
  File "/usr/local/lib/python2.7/urllib2.py", line 435, in open
    response = meth(req, response)
  File "/usr/local/lib/python2.7/urllib2.py", line 548, in http_response
    'http', request, response, code, msg, hdrs)
  File "/usr/local/lib/python2.7/urllib2.py", line 473, in error
    return self._call_chain(*args)
  File "/usr/local/lib/python2.7/urllib2.py", line 407, in _call_chain
    result = func(*args)
  File "/usr/local/lib/python2.7/urllib2.py", line 556, in http_error_default
    raise HTTPError(req.get_full_url(), code, msg, hdrs, fp)
HTTPError: HTTP Error 404: Not Found
2016-07-25 16:59:04,542 - __main__ - DEBUG - there is a error
Traceback (most recent call last):
  File "spyder.py", line 26, in spyder
    MyResponse = urllib2.urlopen(req)
  File "/usr/local/lib/python2.7/urllib2.py", line 154, in urlopen
    return opener.open(url, data, timeout)
  File "/usr/local/lib/python2.7/urllib2.py", line 435, in open
    response = meth(req, response)
  File "/usr/local/lib/python2.7/urllib2.py", line 548, in http_response
    'http', request, response, code, msg, hdrs)
  File "/usr/local/lib/python2.7/urllib2.py", line 473, in error
    return self._call_chain(*args)
  File "/usr/local/lib/python2.7/urllib2.py", line 407, in _call_chain
    result = func(*args)
  File "/usr/local/lib/python2.7/urllib2.py", line 556, in http_error_default
    raise HTTPError(req.get_full_url(), code, msg, hdrs, fp)
HTTPError: HTTP Error 404: Not Found
2016-07-25 17:18:25,289 - __main__ - DEBUG - there is a error
Traceback (most recent call last):
  File "spyder.py", line 35, in spyder
    cur.execute("insert into People_Inf values(?, ?, ?, ?, ?)", (Title_Section[0], None, people, parent, level))
OperationalError: unable to open database file
