2016-07-15 15:06:55,321 - __main__ - DEBUG - there is a error
Traceback (most recent call last):
  File "spyder.py", line 50, in spyder
    cur2.execute('select count(*) from People_Inf where Name_Url=?', (people_list,))
OperationalError: unable to open database file
2016-07-15 15:06:55,387 - __main__ - DEBUG - there is a error
Traceback (most recent call last):
  File "spyder.py", line 50, in spyder
    cur2.execute('select count(*) from People_Inf where Name_Url=?', (people_list,))
OperationalError: unable to open database file
2016-07-15 15:06:55,453 - __main__ - DEBUG - there is a error
Traceback (most recent call last):
  File "spyder.py", line 50, in spyder
    cur2.execute('select count(*) from People_Inf where Name_Url=?', (people_list,))
OperationalError: unable to open database file
2016-07-15 15:06:55,521 - __main__ - DEBUG - there is a error
Traceback (most recent call last):
  File "spyder.py", line 50, in spyder
    cur2.execute('select count(*) from People_Inf where Name_Url=?', (people_list,))
OperationalError: unable to open database file
2016-07-15 15:06:55,588 - __main__ - DEBUG - there is a error
Traceback (most recent call last):
  File "spyder.py", line 50, in spyder
    cur2.execute('select count(*) from People_Inf where Name_Url=?', (people_list,))
OperationalError: unable to open database file
2016-07-15 15:06:55,654 - __main__ - DEBUG - there is a error
Traceback (most recent call last):
  File "spyder.py", line 50, in spyder
    cur2.execute('select count(*) from People_Inf where Name_Url=?', (people_list,))
OperationalError: unable to open database file
2016-07-15 15:06:55,721 - __main__ - DEBUG - there is a error
Traceback (most recent call last):
  File "spyder.py", line 50, in spyder
    cur2.execute('select count(*) from People_Inf where Name_Url=?', (people_list,))
OperationalError: unable to open database file
2016-07-15 15:06:55,787 - __main__ - DEBUG - there is a error
Traceback (most recent call last):
  File "spyder.py", line 50, in spyder
    cur2.execute('select count(*) from People_Inf where Name_Url=?', (people_list,))
OperationalError: unable to open database file
2016-07-15 15:06:55,852 - __main__ - DEBUG - there is a error
Traceback (most recent call last):
  File "spyder.py", line 50, in spyder
    cur2.execute('select count(*) from People_Inf where Name_Url=?', (people_list,))
OperationalError: unable to open database file
2016-07-15 15:06:55,919 - __main__ - DEBUG - there is a error
Traceback (most recent call last):
  File "spyder.py", line 50, in spyder
    cur2.execute('select count(*) from People_Inf where Name_Url=?', (people_list,))
OperationalError: unable to open database file
2016-07-15 15:06:55,989 - __main__ - DEBUG - there is a error
Traceback (most recent call last):
  File "spyder.py", line 50, in spyder
    cur2.execute('select count(*) from People_Inf where Name_Url=?', (people_list,))
OperationalError: unable to open database file
2016-07-15 15:06:56,055 - __main__ - DEBUG - there is a error
Traceback (most recent call last):
  File "spyder.py", line 50, in spyder
    cur2.execute('select count(*) from People_Inf where Name_Url=?', (people_list,))
OperationalError: unable to open database file
2016-07-15 15:06:56,135 - __main__ - DEBUG - there is a error
Traceback (most recent call last):
  File "spyder.py", line 50, in spyder
    cur2.execute('select count(*) from People_Inf where Name_Url=?', (people_list,))
OperationalError: unable to open database file
2016-07-15 15:06:56,204 - __main__ - DEBUG - there is a error
Traceback (most recent call last):
  File "spyder.py", line 50, in spyder
    cur2.execute('select count(*) from People_Inf where Name_Url=?', (people_list,))
OperationalError: unable to open database file
2016-07-15 15:06:56,272 - __main__ - DEBUG - there is a error
Traceback (most recent call last):
  File "spyder.py", line 50, in spyder
    cur2.execute('select count(*) from People_Inf where Name_Url=?', (people_list,))
OperationalError: unable to open database file
2016-07-15 15:06:56,338 - __main__ - DEBUG - there is a error
Traceback (most recent call last):
  File "spyder.py", line 50, in spyder
    cur2.execute('select count(*) from People_Inf where Name_Url=?', (people_list,))
OperationalError: unable to open database file
2016-07-15 15:06:56,404 - __main__ - DEBUG - there is a error
Traceback (most recent call last):
  File "spyder.py", line 50, in spyder
    cur2.execute('select count(*) from People_Inf where Name_Url=?', (people_list,))
OperationalError: unable to open database file
2016-07-15 15:06:56,472 - __main__ - DEBUG - there is a error
Traceback (most recent call last):
  File "spyder.py", line 50, in spyder
    cur2.execute('select count(*) from People_Inf where Name_Url=?', (people_list,))
OperationalError: unable to open database file
2016-07-15 15:06:56,538 - __main__ - DEBUG - there is a error
Traceback (most recent call last):
  File "spyder.py", line 50, in spyder
    cur2.execute('select count(*) from People_Inf where Name_Url=?', (people_list,))
OperationalError: unable to open database file
2016-07-15 15:06:56,605 - __main__ - DEBUG - there is a error
Traceback (most recent call last):
  File "spyder.py", line 50, in spyder
    cur2.execute('select count(*) from People_Inf where Name_Url=?', (people_list,))
OperationalError: unable to open database file
2016-07-15 15:06:56,671 - __main__ - DEBUG - there is a error
Traceback (most recent call last):
  File "spyder.py", line 50, in spyder
    cur2.execute('select count(*) from People_Inf where Name_Url=?', (people_list,))
OperationalError: unable to open database file
2016-07-15 15:06:56,741 - __main__ - DEBUG - there is a error
Traceback (most recent call last):
  File "spyder.py", line 50, in spyder
    cur2.execute('select count(*) from People_Inf where Name_Url=?', (people_list,))
OperationalError: unable to open database file
2016-07-15 15:06:56,816 - __main__ - DEBUG - there is a error
Traceback (most recent call last):
  File "spyder.py", line 50, in spyder
    cur2.execute('select count(*) from People_Inf where Name_Url=?', (people_list,))
OperationalError: unable to open database file
2016-07-15 15:06:56,883 - __main__ - DEBUG - there is a error
Traceback (most recent call last):
  File "spyder.py", line 50, in spyder
    cur2.execute('select count(*) from People_Inf where Name_Url=?', (people_list,))
OperationalError: unable to open database file
2016-07-15 15:06:56,953 - __main__ - DEBUG - there is a error
Traceback (most recent call last):
  File "spyder.py", line 50, in spyder
    cur2.execute('select count(*) from People_Inf where Name_Url=?', (people_list,))
OperationalError: unable to open database file
2016-07-15 15:06:57,054 - __main__ - DEBUG - there is a error
Traceback (most recent call last):
  File "spyder.py", line 50, in spyder
    cur2.execute('select count(*) from People_Inf where Name_Url=?', (people_list,))
OperationalError: unable to open database file
2016-07-15 15:06:57,122 - __main__ - DEBUG - there is a error
Traceback (most recent call last):
  File "spyder.py", line 50, in spyder
    cur2.execute('select count(*) from People_Inf where Name_Url=?', (people_list,))
OperationalError: unable to open database file
2016-07-15 15:06:57,193 - __main__ - DEBUG - there is a error
Traceback (most recent call last):
  File "spyder.py", line 50, in spyder
    cur2.execute('select count(*) from People_Inf where Name_Url=?', (people_list,))
OperationalError: unable to open database file
2016-07-15 15:06:57,260 - __main__ - DEBUG - there is a error
Traceback (most recent call last):
  File "spyder.py", line 50, in spyder
    cur2.execute('select count(*) from People_Inf where Name_Url=?', (people_list,))
OperationalError: unable to open database file
2016-07-15 15:06:57,349 - __main__ - DEBUG - there is a error
Traceback (most recent call last):
  File "spyder.py", line 50, in spyder
    cur2.execute('select count(*) from People_Inf where Name_Url=?', (people_list,))
OperationalError: unable to open database file
2016-07-15 15:06:57,447 - __main__ - DEBUG - there is a error
Traceback (most recent call last):
  File "spyder.py", line 50, in spyder
    cur2.execute('select count(*) from People_Inf where Name_Url=?', (people_list,))
OperationalError: unable to open database file
2016-07-15 15:06:57,549 - __main__ - DEBUG - there is a error
Traceback (most recent call last):
  File "spyder.py", line 50, in spyder
    cur2.execute('select count(*) from People_Inf where Name_Url=?', (people_list,))
OperationalError: unable to open database file
2016-07-15 15:06:57,726 - __main__ - DEBUG - there is a error
Traceback (most recent call last):
  File "spyder.py", line 50, in spyder
    cur2.execute('select count(*) from People_Inf where Name_Url=?', (people_list,))
OperationalError: unable to open database file
2016-07-15 15:06:57,947 - __main__ - DEBUG - there is a error
Traceback (most recent call last):
  File "spyder.py", line 50, in spyder
    cur2.execute('select count(*) from People_Inf where Name_Url=?', (people_list,))
OperationalError: unable to open database file
2016-07-15 15:06:58,186 - __main__ - DEBUG - there is a error
Traceback (most recent call last):
  File "spyder.py", line 50, in spyder
    cur2.execute('select count(*) from People_Inf where Name_Url=?', (people_list,))
OperationalError: unable to open database file
2016-07-15 15:06:58,267 - __main__ - DEBUG - there is a error
Traceback (most recent call last):
  File "spyder.py", line 50, in spyder
    cur2.execute('select count(*) from People_Inf where Name_Url=?', (people_list,))
OperationalError: unable to open database file
2016-07-15 15:06:58,333 - __main__ - DEBUG - there is a error
Traceback (most recent call last):
  File "spyder.py", line 50, in spyder
    cur2.execute('select count(*) from People_Inf where Name_Url=?', (people_list,))
OperationalError: unable to open database file
2016-07-15 15:06:58,402 - __main__ - DEBUG - there is a error
Traceback (most recent call last):
  File "spyder.py", line 50, in spyder
    cur2.execute('select count(*) from People_Inf where Name_Url=?', (people_list,))
OperationalError: unable to open database file
2016-07-15 15:06:58,471 - __main__ - DEBUG - there is a error
Traceback (most recent call last):
  File "spyder.py", line 50, in spyder
    cur2.execute('select count(*) from People_Inf where Name_Url=?', (people_list,))
OperationalError: unable to open database file
2016-07-15 15:06:58,538 - __main__ - DEBUG - there is a error
Traceback (most recent call last):
  File "spyder.py", line 50, in spyder
    cur2.execute('select count(*) from People_Inf where Name_Url=?', (people_list,))
OperationalError: unable to open database file
2016-07-15 15:06:58,605 - __main__ - DEBUG - there is a error
Traceback (most recent call last):
  File "spyder.py", line 50, in spyder
    cur2.execute('select count(*) from People_Inf where Name_Url=?', (people_list,))
OperationalError: unable to open database file
2016-07-15 15:06:58,677 - __main__ - DEBUG - there is a error
Traceback (most recent call last):
  File "spyder.py", line 50, in spyder
    cur2.execute('select count(*) from People_Inf where Name_Url=?', (people_list,))
OperationalError: unable to open database file
2016-07-15 15:06:58,743 - __main__ - DEBUG - there is a error
Traceback (most recent call last):
  File "spyder.py", line 50, in spyder
    cur2.execute('select count(*) from People_Inf where Name_Url=?', (people_list,))
OperationalError: unable to open database file
2016-07-15 15:06:58,810 - __main__ - DEBUG - there is a error
Traceback (most recent call last):
  File "spyder.py", line 50, in spyder
    cur2.execute('select count(*) from People_Inf where Name_Url=?', (people_list,))
OperationalError: unable to open database file
2016-07-15 15:06:58,879 - __main__ - DEBUG - there is a error
Traceback (most recent call last):
  File "spyder.py", line 50, in spyder
    cur2.execute('select count(*) from People_Inf where Name_Url=?', (people_list,))
OperationalError: unable to open database file
2016-07-15 15:06:58,947 - __main__ - DEBUG - there is a error
Traceback (most recent call last):
  File "spyder.py", line 50, in spyder
    cur2.execute('select count(*) from People_Inf where Name_Url=?', (people_list,))
OperationalError: unable to open database file
2016-07-15 15:06:59,019 - __main__ - DEBUG - there is a error
Traceback (most recent call last):
  File "spyder.py", line 50, in spyder
    cur2.execute('select count(*) from People_Inf where Name_Url=?', (people_list,))
OperationalError: unable to open database file
2016-07-15 15:06:59,087 - __main__ - DEBUG - there is a error
Traceback (most recent call last):
  File "spyder.py", line 50, in spyder
    cur2.execute('select count(*) from People_Inf where Name_Url=?', (people_list,))
OperationalError: unable to open database file
2016-07-15 15:06:59,155 - __main__ - DEBUG - there is a error
Traceback (most recent call last):
  File "spyder.py", line 50, in spyder
    cur2.execute('select count(*) from People_Inf where Name_Url=?', (people_list,))
OperationalError: unable to open database file
2016-07-15 15:06:59,221 - __main__ - DEBUG - there is a error
Traceback (most recent call last):
  File "spyder.py", line 50, in spyder
    cur2.execute('select count(*) from People_Inf where Name_Url=?', (people_list,))
OperationalError: unable to open database file
2016-07-15 15:06:59,287 - __main__ - DEBUG - there is a error
Traceback (most recent call last):
  File "spyder.py", line 50, in spyder
    cur2.execute('select count(*) from People_Inf where Name_Url=?', (people_list,))
OperationalError: unable to open database file
2016-07-15 15:06:59,352 - __main__ - DEBUG - there is a error
Traceback (most recent call last):
  File "spyder.py", line 50, in spyder
    cur2.execute('select count(*) from People_Inf where Name_Url=?', (people_list,))
OperationalError: unable to open database file
2016-07-15 15:06:59,453 - __main__ - DEBUG - there is a error
Traceback (most recent call last):
  File "spyder.py", line 50, in spyder
    cur2.execute('select count(*) from People_Inf where Name_Url=?', (people_list,))
OperationalError: unable to open database file
2016-07-15 15:06:59,521 - __main__ - DEBUG - there is a error
Traceback (most recent call last):
  File "spyder.py", line 50, in spyder
    cur2.execute('select count(*) from People_Inf where Name_Url=?', (people_list,))
OperationalError: unable to open database file
2016-07-15 15:06:59,587 - __main__ - DEBUG - there is a error
Traceback (most recent call last):
  File "spyder.py", line 50, in spyder
    cur2.execute('select count(*) from People_Inf where Name_Url=?', (people_list,))
OperationalError: unable to open database file
2016-07-15 15:06:59,655 - __main__ - DEBUG - there is a error
Traceback (most recent call last):
  File "spyder.py", line 50, in spyder
    cur2.execute('select count(*) from People_Inf where Name_Url=?', (people_list,))
OperationalError: unable to open database file
2016-07-15 15:06:59,746 - __main__ - DEBUG - there is a error
Traceback (most recent call last):
  File "spyder.py", line 50, in spyder
    cur2.execute('select count(*) from People_Inf where Name_Url=?', (people_list,))
OperationalError: unable to open database file
2016-07-15 15:06:59,816 - __main__ - DEBUG - there is a error
Traceback (most recent call last):
  File "spyder.py", line 50, in spyder
    cur2.execute('select count(*) from People_Inf where Name_Url=?', (people_list,))
OperationalError: unable to open database file
2016-07-15 15:06:59,891 - __main__ - DEBUG - there is a error
Traceback (most recent call last):
  File "spyder.py", line 50, in spyder
    cur2.execute('select count(*) from People_Inf where Name_Url=?', (people_list,))
OperationalError: unable to open database file
2016-07-15 15:06:59,970 - __main__ - DEBUG - there is a error
Traceback (most recent call last):
  File "spyder.py", line 50, in spyder
    cur2.execute('select count(*) from People_Inf where Name_Url=?', (people_list,))
OperationalError: unable to open database file
2016-07-15 15:07:00,039 - __main__ - DEBUG - there is a error
Traceback (most recent call last):
  File "spyder.py", line 50, in spyder
    cur2.execute('select count(*) from People_Inf where Name_Url=?', (people_list,))
OperationalError: unable to open database file
2016-07-15 15:07:00,110 - __main__ - DEBUG - there is a error
Traceback (most recent call last):
  File "spyder.py", line 50, in spyder
    cur2.execute('select count(*) from People_Inf where Name_Url=?', (people_list,))
OperationalError: unable to open database file
2016-07-15 15:07:00,179 - __main__ - DEBUG - there is a error
Traceback (most recent call last):
  File "spyder.py", line 50, in spyder
    cur2.execute('select count(*) from People_Inf where Name_Url=?', (people_list,))
OperationalError: unable to open database file
2016-07-15 15:07:00,247 - __main__ - DEBUG - there is a error
Traceback (most recent call last):
  File "spyder.py", line 50, in spyder
    cur2.execute('select count(*) from People_Inf where Name_Url=?', (people_list,))
OperationalError: unable to open database file
2016-07-15 15:07:00,313 - __main__ - DEBUG - there is a error
Traceback (most recent call last):
  File "spyder.py", line 50, in spyder
    cur2.execute('select count(*) from People_Inf where Name_Url=?', (people_list,))
OperationalError: unable to open database file
2016-07-15 15:07:00,380 - __main__ - DEBUG - there is a error
Traceback (most recent call last):
  File "spyder.py", line 50, in spyder
    cur2.execute('select count(*) from People_Inf where Name_Url=?', (people_list,))
OperationalError: unable to open database file
2016-07-15 15:07:00,448 - __main__ - DEBUG - there is a error
Traceback (most recent call last):
  File "spyder.py", line 50, in spyder
    cur2.execute('select count(*) from People_Inf where Name_Url=?', (people_list,))
OperationalError: unable to open database file
2016-07-15 15:07:00,515 - __main__ - DEBUG - there is a error
Traceback (most recent call last):
  File "spyder.py", line 50, in spyder
    cur2.execute('select count(*) from People_Inf where Name_Url=?', (people_list,))
OperationalError: unable to open database file
2016-07-15 15:07:00,583 - __main__ - DEBUG - there is a error
Traceback (most recent call last):
  File "spyder.py", line 50, in spyder
    cur2.execute('select count(*) from People_Inf where Name_Url=?', (people_list,))
OperationalError: unable to open database file
2016-07-15 15:07:00,655 - __main__ - DEBUG - there is a error
Traceback (most recent call last):
  File "spyder.py", line 50, in spyder
    cur2.execute('select count(*) from People_Inf where Name_Url=?', (people_list,))
OperationalError: unable to open database file
2016-07-15 15:07:00,728 - __main__ - DEBUG - there is a error
Traceback (most recent call last):
  File "spyder.py", line 50, in spyder
    cur2.execute('select count(*) from People_Inf where Name_Url=?', (people_list,))
OperationalError: unable to open database file
2016-07-15 15:07:00,808 - __main__ - DEBUG - there is a error
Traceback (most recent call last):
  File "spyder.py", line 50, in spyder
    cur2.execute('select count(*) from People_Inf where Name_Url=?', (people_list,))
OperationalError: unable to open database file
2016-07-15 15:07:00,880 - __main__ - DEBUG - there is a error
Traceback (most recent call last):
  File "spyder.py", line 50, in spyder
    cur2.execute('select count(*) from People_Inf where Name_Url=?', (people_list,))
OperationalError: unable to open database file
2016-07-15 15:07:00,959 - __main__ - DEBUG - there is a error
Traceback (most recent call last):
  File "spyder.py", line 50, in spyder
    cur2.execute('select count(*) from People_Inf where Name_Url=?', (people_list,))
OperationalError: unable to open database file
2016-07-15 15:07:01,037 - __main__ - DEBUG - there is a error
Traceback (most recent call last):
  File "spyder.py", line 50, in spyder
    cur2.execute('select count(*) from People_Inf where Name_Url=?', (people_list,))
OperationalError: unable to open database file
2016-07-15 15:07:01,116 - __main__ - DEBUG - there is a error
Traceback (most recent call last):
  File "spyder.py", line 50, in spyder
    cur2.execute('select count(*) from People_Inf where Name_Url=?', (people_list,))
OperationalError: unable to open database file
2016-07-15 15:07:01,190 - __main__ - DEBUG - there is a error
Traceback (most recent call last):
  File "spyder.py", line 50, in spyder
    cur2.execute('select count(*) from People_Inf where Name_Url=?', (people_list,))
OperationalError: unable to open database file
2016-07-15 15:07:01,266 - __main__ - DEBUG - there is a error
Traceback (most recent call last):
  File "spyder.py", line 50, in spyder
    cur2.execute('select count(*) from People_Inf where Name_Url=?', (people_list,))
OperationalError: unable to open database file
2016-07-15 15:07:01,337 - __main__ - DEBUG - there is a error
Traceback (most recent call last):
  File "spyder.py", line 50, in spyder
    cur2.execute('select count(*) from People_Inf where Name_Url=?', (people_list,))
OperationalError: unable to open database file
2016-07-15 15:07:01,408 - __main__ - DEBUG - there is a error
Traceback (most recent call last):
  File "spyder.py", line 50, in spyder
    cur2.execute('select count(*) from People_Inf where Name_Url=?', (people_list,))
OperationalError: unable to open database file
2016-07-15 15:07:01,481 - __main__ - DEBUG - there is a error
Traceback (most recent call last):
  File "spyder.py", line 50, in spyder
    cur2.execute('select count(*) from People_Inf where Name_Url=?', (people_list,))
OperationalError: unable to open database file
2016-07-15 15:07:01,551 - __main__ - DEBUG - there is a error
Traceback (most recent call last):
  File "spyder.py", line 50, in spyder
    cur2.execute('select count(*) from People_Inf where Name_Url=?', (people_list,))
OperationalError: unable to open database file
2016-07-15 15:07:01,624 - __main__ - DEBUG - there is a error
Traceback (most recent call last):
  File "spyder.py", line 50, in spyder
    cur2.execute('select count(*) from People_Inf where Name_Url=?', (people_list,))
OperationalError: unable to open database file
2016-07-15 15:07:01,695 - __main__ - DEBUG - there is a error
Traceback (most recent call last):
  File "spyder.py", line 50, in spyder
    cur2.execute('select count(*) from People_Inf where Name_Url=?', (people_list,))
OperationalError: unable to open database file
2016-07-15 15:07:01,796 - __main__ - DEBUG - there is a error
Traceback (most recent call last):
  File "spyder.py", line 50, in spyder
    cur2.execute('select count(*) from People_Inf where Name_Url=?', (people_list,))
OperationalError: unable to open database file
2016-07-15 15:07:01,877 - __main__ - DEBUG - there is a error
Traceback (most recent call last):
  File "spyder.py", line 50, in spyder
    cur2.execute('select count(*) from People_Inf where Name_Url=?', (people_list,))
OperationalError: unable to open database file
2016-07-15 15:07:01,951 - __main__ - DEBUG - there is a error
Traceback (most recent call last):
  File "spyder.py", line 50, in spyder
    cur2.execute('select count(*) from People_Inf where Name_Url=?', (people_list,))
OperationalError: unable to open database file
2016-07-15 15:07:02,043 - __main__ - DEBUG - there is a error
Traceback (most recent call last):
  File "spyder.py", line 50, in spyder
    cur2.execute('select count(*) from People_Inf where Name_Url=?', (people_list,))
OperationalError: unable to open database file
2016-07-15 15:07:02,116 - __main__ - DEBUG - there is a error
Traceback (most recent call last):
  File "spyder.py", line 50, in spyder
    cur2.execute('select count(*) from People_Inf where Name_Url=?', (people_list,))
OperationalError: unable to open database file
2016-07-15 15:07:02,184 - __main__ - DEBUG - there is a error
Traceback (most recent call last):
  File "spyder.py", line 50, in spyder
    cur2.execute('select count(*) from People_Inf where Name_Url=?', (people_list,))
OperationalError: unable to open database file
2016-07-15 15:07:02,305 - __main__ - DEBUG - there is a error
Traceback (most recent call last):
  File "spyder.py", line 50, in spyder
    cur2.execute('select count(*) from People_Inf where Name_Url=?', (people_list,))
OperationalError: unable to open database file
2016-07-15 15:07:02,401 - __main__ - DEBUG - there is a error
Traceback (most recent call last):
  File "spyder.py", line 50, in spyder
    cur2.execute('select count(*) from People_Inf where Name_Url=?', (people_list,))
OperationalError: unable to open database file
2016-07-15 15:07:02,580 - __main__ - DEBUG - there is a error
Traceback (most recent call last):
  File "spyder.py", line 50, in spyder
    cur2.execute('select count(*) from People_Inf where Name_Url=?', (people_list,))
OperationalError: unable to open database file
2016-07-15 15:07:02,667 - __main__ - DEBUG - there is a error
Traceback (most recent call last):
  File "spyder.py", line 50, in spyder
    cur2.execute('select count(*) from People_Inf where Name_Url=?', (people_list,))
OperationalError: unable to open database file
2016-07-15 15:07:02,742 - __main__ - DEBUG - there is a error
Traceback (most recent call last):
  File "spyder.py", line 50, in spyder
    cur2.execute('select count(*) from People_Inf where Name_Url=?', (people_list,))
OperationalError: unable to open database file
2016-07-15 15:07:02,815 - __main__ - DEBUG - there is a error
Traceback (most recent call last):
  File "spyder.py", line 50, in spyder
    cur2.execute('select count(*) from People_Inf where Name_Url=?', (people_list,))
OperationalError: unable to open database file
2016-07-15 15:07:02,890 - __main__ - DEBUG - there is a error
Traceback (most recent call last):
  File "spyder.py", line 50, in spyder
    cur2.execute('select count(*) from People_Inf where Name_Url=?', (people_list,))
OperationalError: unable to open database file
2016-07-15 15:07:02,981 - __main__ - DEBUG - there is a error
Traceback (most recent call last):
  File "spyder.py", line 50, in spyder
    cur2.execute('select count(*) from People_Inf where Name_Url=?', (people_list,))
OperationalError: unable to open database file
2016-07-15 15:07:03,083 - __main__ - DEBUG - there is a error
Traceback (most recent call last):
  File "spyder.py", line 50, in spyder
    cur2.execute('select count(*) from People_Inf where Name_Url=?', (people_list,))
OperationalError: unable to open database file
2016-07-15 15:07:03,188 - __main__ - DEBUG - there is a error
Traceback (most recent call last):
  File "spyder.py", line 50, in spyder
    cur2.execute('select count(*) from People_Inf where Name_Url=?', (people_list,))
OperationalError: unable to open database file
2016-07-15 15:07:03,274 - __main__ - DEBUG - there is a error
Traceback (most recent call last):
  File "spyder.py", line 50, in spyder
    cur2.execute('select count(*) from People_Inf where Name_Url=?', (people_list,))
OperationalError: unable to open database file
2016-07-15 15:07:03,355 - __main__ - DEBUG - there is a error
Traceback (most recent call last):
  File "spyder.py", line 50, in spyder
    cur2.execute('select count(*) from People_Inf where Name_Url=?', (people_list,))
OperationalError: unable to open database file
2016-07-15 15:07:03,625 - __main__ - DEBUG - there is a error
Traceback (most recent call last):
  File "spyder.py", line 50, in spyder
    cur2.execute('select count(*) from People_Inf where Name_Url=?', (people_list,))
OperationalError: unable to open database file
2016-07-15 15:07:03,818 - __main__ - DEBUG - there is a error
Traceback (most recent call last):
  File "spyder.py", line 50, in spyder
    cur2.execute('select count(*) from People_Inf where Name_Url=?', (people_list,))
OperationalError: unable to open database file
2016-07-15 15:07:03,923 - __main__ - DEBUG - there is a error
Traceback (most recent call last):
  File "spyder.py", line 50, in spyder
    cur2.execute('select count(*) from People_Inf where Name_Url=?', (people_list,))
OperationalError: unable to open database file
2016-07-15 15:07:04,008 - __main__ - DEBUG - there is a error
Traceback (most recent call last):
  File "spyder.py", line 50, in spyder
    cur2.execute('select count(*) from People_Inf where Name_Url=?', (people_list,))
OperationalError: unable to open database file
2016-07-15 15:07:04,092 - __main__ - DEBUG - there is a error
Traceback (most recent call last):
  File "spyder.py", line 50, in spyder
    cur2.execute('select count(*) from People_Inf where Name_Url=?', (people_list,))
OperationalError: unable to open database file
2016-07-15 15:07:04,221 - __main__ - DEBUG - there is a error
Traceback (most recent call last):
  File "spyder.py", line 50, in spyder
    cur2.execute('select count(*) from People_Inf where Name_Url=?', (people_list,))
OperationalError: unable to open database file
2016-07-15 15:07:04,329 - __main__ - DEBUG - there is a error
Traceback (most recent call last):
  File "spyder.py", line 50, in spyder
    cur2.execute('select count(*) from People_Inf where Name_Url=?', (people_list,))
OperationalError: unable to open database file
2016-07-15 15:07:04,406 - __main__ - DEBUG - there is a error
Traceback (most recent call last):
  File "spyder.py", line 50, in spyder
    cur2.execute('select count(*) from People_Inf where Name_Url=?', (people_list,))
OperationalError: unable to open database file
2016-07-15 15:07:04,483 - __main__ - DEBUG - there is a error
Traceback (most recent call last):
  File "spyder.py", line 50, in spyder
    cur2.execute('select count(*) from People_Inf where Name_Url=?', (people_list,))
OperationalError: unable to open database file
2016-07-15 15:07:04,582 - __main__ - DEBUG - there is a error
Traceback (most recent call last):
  File "spyder.py", line 50, in spyder
    cur2.execute('select count(*) from People_Inf where Name_Url=?', (people_list,))
OperationalError: unable to open database file
2016-07-15 15:07:04,660 - __main__ - DEBUG - there is a error
Traceback (most recent call last):
  File "spyder.py", line 50, in spyder
    cur2.execute('select count(*) from People_Inf where Name_Url=?', (people_list,))
OperationalError: unable to open database file
2016-07-15 15:07:04,742 - __main__ - DEBUG - there is a error
Traceback (most recent call last):
  File "spyder.py", line 50, in spyder
    cur2.execute('select count(*) from People_Inf where Name_Url=?', (people_list,))
OperationalError: unable to open database file
2016-07-15 15:07:04,819 - __main__ - DEBUG - there is a error
Traceback (most recent call last):
  File "spyder.py", line 50, in spyder
    cur2.execute('select count(*) from People_Inf where Name_Url=?', (people_list,))
OperationalError: unable to open database file
2016-07-15 15:07:04,925 - __main__ - DEBUG - there is a error
Traceback (most recent call last):
  File "spyder.py", line 50, in spyder
    cur2.execute('select count(*) from People_Inf where Name_Url=?', (people_list,))
OperationalError: unable to open database file
2016-07-15 15:07:05,020 - __main__ - DEBUG - there is a error
Traceback (most recent call last):
  File "spyder.py", line 50, in spyder
    cur2.execute('select count(*) from People_Inf where Name_Url=?', (people_list,))
OperationalError: unable to open database file
2016-07-15 15:07:05,092 - __main__ - DEBUG - there is a error
Traceback (most recent call last):
  File "spyder.py", line 50, in spyder
    cur2.execute('select count(*) from People_Inf where Name_Url=?', (people_list,))
OperationalError: unable to open database file
2016-07-15 15:07:05,164 - __main__ - DEBUG - there is a error
Traceback (most recent call last):
  File "spyder.py", line 50, in spyder
    cur2.execute('select count(*) from People_Inf where Name_Url=?', (people_list,))
OperationalError: unable to open database file
2016-07-15 15:07:05,245 - __main__ - DEBUG - there is a error
Traceback (most recent call last):
  File "spyder.py", line 50, in spyder
    cur2.execute('select count(*) from People_Inf where Name_Url=?', (people_list,))
OperationalError: unable to open database file
2016-07-15 15:07:05,341 - __main__ - DEBUG - there is a error
Traceback (most recent call last):
  File "spyder.py", line 50, in spyder
    cur2.execute('select count(*) from People_Inf where Name_Url=?', (people_list,))
OperationalError: unable to open database file
2016-07-15 15:07:05,410 - __main__ - DEBUG - there is a error
Traceback (most recent call last):
  File "spyder.py", line 50, in spyder
    cur2.execute('select count(*) from People_Inf where Name_Url=?', (people_list,))
OperationalError: unable to open database file
2016-07-15 15:07:05,480 - __main__ - DEBUG - there is a error
Traceback (most recent call last):
  File "spyder.py", line 50, in spyder
    cur2.execute('select count(*) from People_Inf where Name_Url=?', (people_list,))
OperationalError: unable to open database file
2016-07-15 15:07:05,547 - __main__ - DEBUG - there is a error
Traceback (most recent call last):
  File "spyder.py", line 50, in spyder
    cur2.execute('select count(*) from People_Inf where Name_Url=?', (people_list,))
OperationalError: unable to open database file
2016-07-15 15:07:05,677 - __main__ - DEBUG - there is a error
Traceback (most recent call last):
  File "spyder.py", line 50, in spyder
    cur2.execute('select count(*) from People_Inf where Name_Url=?', (people_list,))
OperationalError: unable to open database file
2016-07-15 15:07:05,814 - __main__ - DEBUG - there is a error
Traceback (most recent call last):
  File "spyder.py", line 50, in spyder
    cur2.execute('select count(*) from People_Inf where Name_Url=?', (people_list,))
OperationalError: unable to open database file
2016-07-15 15:07:05,924 - __main__ - DEBUG - there is a error
Traceback (most recent call last):
  File "spyder.py", line 50, in spyder
    cur2.execute('select count(*) from People_Inf where Name_Url=?', (people_list,))
OperationalError: unable to open database file
2016-07-15 15:07:06,020 - __main__ - DEBUG - there is a error
Traceback (most recent call last):
  File "spyder.py", line 50, in spyder
    cur2.execute('select count(*) from People_Inf where Name_Url=?', (people_list,))
OperationalError: unable to open database file
2016-07-15 15:07:06,106 - __main__ - DEBUG - there is a error
Traceback (most recent call last):
  File "spyder.py", line 50, in spyder
    cur2.execute('select count(*) from People_Inf where Name_Url=?', (people_list,))
OperationalError: unable to open database file
2016-07-15 15:07:06,178 - __main__ - DEBUG - there is a error
Traceback (most recent call last):
  File "spyder.py", line 50, in spyder
    cur2.execute('select count(*) from People_Inf where Name_Url=?', (people_list,))
OperationalError: unable to open database file
2016-07-15 15:07:06,251 - __main__ - DEBUG - there is a error
Traceback (most recent call last):
  File "spyder.py", line 50, in spyder
    cur2.execute('select count(*) from People_Inf where Name_Url=?', (people_list,))
OperationalError: unable to open database file
2016-07-15 15:07:07,490 - __main__ - DEBUG - there is a error
Traceback (most recent call last):
  File "spyder.py", line 50, in spyder
    cur2.execute('select count(*) from People_Inf where Name_Url=?', (people_list,))
OperationalError: unable to open database file
2016-07-15 15:07:07,846 - __main__ - DEBUG - there is a error
Traceback (most recent call last):
  File "spyder.py", line 50, in spyder
    cur2.execute('select count(*) from People_Inf where Name_Url=?', (people_list,))
OperationalError: unable to open database file
2016-07-15 15:07:07,938 - __main__ - DEBUG - there is a error
Traceback (most recent call last):
  File "spyder.py", line 50, in spyder
    cur2.execute('select count(*) from People_Inf where Name_Url=?', (people_list,))
OperationalError: unable to open database file
2016-07-15 15:07:08,006 - __main__ - DEBUG - there is a error
Traceback (most recent call last):
  File "spyder.py", line 50, in spyder
    cur2.execute('select count(*) from People_Inf where Name_Url=?', (people_list,))
OperationalError: unable to open database file
2016-07-15 15:07:08,077 - __main__ - DEBUG - there is a error
Traceback (most recent call last):
  File "spyder.py", line 50, in spyder
    cur2.execute('select count(*) from People_Inf where Name_Url=?', (people_list,))
OperationalError: unable to open database file
2016-07-15 15:07:08,160 - __main__ - DEBUG - there is a error
Traceback (most recent call last):
  File "spyder.py", line 50, in spyder
    cur2.execute('select count(*) from People_Inf where Name_Url=?', (people_list,))
OperationalError: unable to open database file
2016-07-15 15:07:08,228 - __main__ - DEBUG - there is a error
Traceback (most recent call last):
  File "spyder.py", line 50, in spyder
    cur2.execute('select count(*) from People_Inf where Name_Url=?', (people_list,))
OperationalError: unable to open database file
2016-07-15 15:07:08,298 - __main__ - DEBUG - there is a error
Traceback (most recent call last):
  File "spyder.py", line 50, in spyder
    cur2.execute('select count(*) from People_Inf where Name_Url=?', (people_list,))
OperationalError: unable to open database file
2016-07-15 15:07:08,365 - __main__ - DEBUG - there is a error
Traceback (most recent call last):
  File "spyder.py", line 50, in spyder
    cur2.execute('select count(*) from People_Inf where Name_Url=?', (people_list,))
OperationalError: unable to open database file
2016-07-15 15:07:08,433 - __main__ - DEBUG - there is a error
Traceback (most recent call last):
  File "spyder.py", line 50, in spyder
    cur2.execute('select count(*) from People_Inf where Name_Url=?', (people_list,))
OperationalError: unable to open database file
2016-07-15 15:07:08,513 - __main__ - DEBUG - there is a error
Traceback (most recent call last):
  File "spyder.py", line 50, in spyder
    cur2.execute('select count(*) from People_Inf where Name_Url=?', (people_list,))
OperationalError: unable to open database file
2016-07-15 15:07:08,590 - __main__ - DEBUG - there is a error
Traceback (most recent call last):
  File "spyder.py", line 50, in spyder
    cur2.execute('select count(*) from People_Inf where Name_Url=?', (people_list,))
OperationalError: unable to open database file
2016-07-15 15:07:08,655 - __main__ - DEBUG - there is a error
Traceback (most recent call last):
  File "spyder.py", line 50, in spyder
    cur2.execute('select count(*) from People_Inf where Name_Url=?', (people_list,))
OperationalError: unable to open database file
2016-07-15 15:07:08,721 - __main__ - DEBUG - there is a error
Traceback (most recent call last):
  File "spyder.py", line 50, in spyder
    cur2.execute('select count(*) from People_Inf where Name_Url=?', (people_list,))
OperationalError: unable to open database file
2016-07-15 15:07:08,787 - __main__ - DEBUG - there is a error
Traceback (most recent call last):
  File "spyder.py", line 50, in spyder
    cur2.execute('select count(*) from People_Inf where Name_Url=?', (people_list,))
OperationalError: unable to open database file
2016-07-15 15:07:08,871 - __main__ - DEBUG - there is a error
Traceback (most recent call last):
  File "spyder.py", line 50, in spyder
    cur2.execute('select count(*) from People_Inf where Name_Url=?', (people_list,))
OperationalError: unable to open database file
2016-07-15 15:07:08,943 - __main__ - DEBUG - there is a error
Traceback (most recent call last):
  File "spyder.py", line 50, in spyder
    cur2.execute('select count(*) from People_Inf where Name_Url=?', (people_list,))
OperationalError: unable to open database file
2016-07-15 15:07:09,034 - __main__ - DEBUG - there is a error
Traceback (most recent call last):
  File "spyder.py", line 50, in spyder
    cur2.execute('select count(*) from People_Inf where Name_Url=?', (people_list,))
OperationalError: unable to open database file
2016-07-15 15:07:09,204 - __main__ - DEBUG - there is a error
Traceback (most recent call last):
  File "spyder.py", line 50, in spyder
    cur2.execute('select count(*) from People_Inf where Name_Url=?', (people_list,))
OperationalError: unable to open database file
2016-07-15 15:07:09,294 - __main__ - DEBUG - there is a error
Traceback (most recent call last):
  File "spyder.py", line 50, in spyder
    cur2.execute('select count(*) from People_Inf where Name_Url=?', (people_list,))
OperationalError: unable to open database file
2016-07-15 15:07:09,441 - __main__ - DEBUG - there is a error
Traceback (most recent call last):
  File "spyder.py", line 50, in spyder
    cur2.execute('select count(*) from People_Inf where Name_Url=?', (people_list,))
OperationalError: unable to open database file
2016-07-15 15:07:09,554 - __main__ - DEBUG - there is a error
Traceback (most recent call last):
  File "spyder.py", line 50, in spyder
    cur2.execute('select count(*) from People_Inf where Name_Url=?', (people_list,))
OperationalError: unable to open database file
2016-07-15 15:07:09,637 - __main__ - DEBUG - there is a error
Traceback (most recent call last):
  File "spyder.py", line 50, in spyder
    cur2.execute('select count(*) from People_Inf where Name_Url=?', (people_list,))
OperationalError: unable to open database file
2016-07-15 15:07:09,704 - __main__ - DEBUG - there is a error
Traceback (most recent call last):
  File "spyder.py", line 50, in spyder
    cur2.execute('select count(*) from People_Inf where Name_Url=?', (people_list,))
OperationalError: unable to open database file
2016-07-15 15:07:09,772 - __main__ - DEBUG - there is a error
Traceback (most recent call last):
  File "spyder.py", line 50, in spyder
    cur2.execute('select count(*) from People_Inf where Name_Url=?', (people_list,))
OperationalError: unable to open database file
2016-07-15 15:07:09,849 - __main__ - DEBUG - there is a error
Traceback (most recent call last):
  File "spyder.py", line 50, in spyder
    cur2.execute('select count(*) from People_Inf where Name_Url=?', (people_list,))
OperationalError: unable to open database file
2016-07-15 15:07:09,916 - __main__ - DEBUG - there is a error
Traceback (most recent call last):
  File "spyder.py", line 50, in spyder
    cur2.execute('select count(*) from People_Inf where Name_Url=?', (people_list,))
OperationalError: unable to open database file
2016-07-15 15:07:09,983 - __main__ - DEBUG - there is a error
Traceback (most recent call last):
  File "spyder.py", line 50, in spyder
    cur2.execute('select count(*) from People_Inf where Name_Url=?', (people_list,))
OperationalError: unable to open database file
2016-07-15 15:07:10,050 - __main__ - DEBUG - there is a error
Traceback (most recent call last):
  File "spyder.py", line 50, in spyder
    cur2.execute('select count(*) from People_Inf where Name_Url=?', (people_list,))
OperationalError: unable to open database file
2016-07-15 15:07:10,118 - __main__ - DEBUG - there is a error
Traceback (most recent call last):
  File "spyder.py", line 50, in spyder
    cur2.execute('select count(*) from People_Inf where Name_Url=?', (people_list,))
OperationalError: unable to open database file
2016-07-15 15:07:10,185 - __main__ - DEBUG - there is a error
Traceback (most recent call last):
  File "spyder.py", line 50, in spyder
    cur2.execute('select count(*) from People_Inf where Name_Url=?', (people_list,))
OperationalError: unable to open database file
2016-07-15 15:07:10,278 - __main__ - DEBUG - there is a error
Traceback (most recent call last):
  File "spyder.py", line 50, in spyder
    cur2.execute('select count(*) from People_Inf where Name_Url=?', (people_list,))
OperationalError: unable to open database file
2016-07-15 15:07:10,354 - __main__ - DEBUG - there is a error
Traceback (most recent call last):
  File "spyder.py", line 50, in spyder
    cur2.execute('select count(*) from People_Inf where Name_Url=?', (people_list,))
OperationalError: unable to open database file
2016-07-15 15:07:10,425 - __main__ - DEBUG - there is a error
Traceback (most recent call last):
  File "spyder.py", line 50, in spyder
    cur2.execute('select count(*) from People_Inf where Name_Url=?', (people_list,))
OperationalError: unable to open database file
2016-07-15 15:07:10,502 - __main__ - DEBUG - there is a error
Traceback (most recent call last):
  File "spyder.py", line 50, in spyder
    cur2.execute('select count(*) from People_Inf where Name_Url=?', (people_list,))
OperationalError: unable to open database file
2016-07-15 15:07:10,571 - __main__ - DEBUG - there is a error
Traceback (most recent call last):
  File "spyder.py", line 50, in spyder
    cur2.execute('select count(*) from People_Inf where Name_Url=?', (people_list,))
OperationalError: unable to open database file
2016-07-15 15:07:10,641 - __main__ - DEBUG - there is a error
Traceback (most recent call last):
  File "spyder.py", line 50, in spyder
    cur2.execute('select count(*) from People_Inf where Name_Url=?', (people_list,))
OperationalError: unable to open database file
2016-07-15 15:07:10,708 - __main__ - DEBUG - there is a error
Traceback (most recent call last):
  File "spyder.py", line 50, in spyder
    cur2.execute('select count(*) from People_Inf where Name_Url=?', (people_list,))
OperationalError: unable to open database file
2016-07-15 15:07:10,775 - __main__ - DEBUG - there is a error
Traceback (most recent call last):
  File "spyder.py", line 50, in spyder
    cur2.execute('select count(*) from People_Inf where Name_Url=?', (people_list,))
OperationalError: unable to open database file
2016-07-15 15:07:10,842 - __main__ - DEBUG - there is a error
Traceback (most recent call last):
  File "spyder.py", line 50, in spyder
    cur2.execute('select count(*) from People_Inf where Name_Url=?', (people_list,))
OperationalError: unable to open database file
2016-07-15 15:07:10,932 - __main__ - DEBUG - there is a error
Traceback (most recent call last):
  File "spyder.py", line 50, in spyder
    cur2.execute('select count(*) from People_Inf where Name_Url=?', (people_list,))
OperationalError: unable to open database file
2016-07-15 15:07:11,000 - __main__ - DEBUG - there is a error
Traceback (most recent call last):
  File "spyder.py", line 50, in spyder
    cur2.execute('select count(*) from People_Inf where Name_Url=?', (people_list,))
OperationalError: unable to open database file
2016-07-15 15:07:11,081 - __main__ - DEBUG - there is a error
Traceback (most recent call last):
  File "spyder.py", line 50, in spyder
    cur2.execute('select count(*) from People_Inf where Name_Url=?', (people_list,))
OperationalError: unable to open database file
2016-07-15 15:07:11,151 - __main__ - DEBUG - there is a error
Traceback (most recent call last):
  File "spyder.py", line 50, in spyder
    cur2.execute('select count(*) from People_Inf where Name_Url=?', (people_list,))
OperationalError: unable to open database file
2016-07-15 15:07:11,217 - __main__ - DEBUG - there is a error
Traceback (most recent call last):
  File "spyder.py", line 50, in spyder
    cur2.execute('select count(*) from People_Inf where Name_Url=?', (people_list,))
OperationalError: unable to open database file
2016-07-15 15:07:11,284 - __main__ - DEBUG - there is a error
Traceback (most recent call last):
  File "spyder.py", line 50, in spyder
    cur2.execute('select count(*) from People_Inf where Name_Url=?', (people_list,))
OperationalError: unable to open database file
2016-07-15 15:07:11,370 - __main__ - DEBUG - there is a error
Traceback (most recent call last):
  File "spyder.py", line 50, in spyder
    cur2.execute('select count(*) from People_Inf where Name_Url=?', (people_list,))
OperationalError: unable to open database file
2016-07-15 15:07:11,450 - __main__ - DEBUG - there is a error
Traceback (most recent call last):
  File "spyder.py", line 50, in spyder
    cur2.execute('select count(*) from People_Inf where Name_Url=?', (people_list,))
OperationalError: unable to open database file
2016-07-15 15:07:11,520 - __main__ - DEBUG - there is a error
Traceback (most recent call last):
  File "spyder.py", line 50, in spyder
    cur2.execute('select count(*) from People_Inf where Name_Url=?', (people_list,))
OperationalError: unable to open database file
2016-07-15 15:07:11,587 - __main__ - DEBUG - there is a error
Traceback (most recent call last):
  File "spyder.py", line 50, in spyder
    cur2.execute('select count(*) from People_Inf where Name_Url=?', (people_list,))
OperationalError: unable to open database file
2016-07-15 15:07:11,654 - __main__ - DEBUG - there is a error
Traceback (most recent call last):
  File "spyder.py", line 50, in spyder
    cur2.execute('select count(*) from People_Inf where Name_Url=?', (people_list,))
OperationalError: unable to open database file
2016-07-15 15:07:11,733 - __main__ - DEBUG - there is a error
Traceback (most recent call last):
  File "spyder.py", line 50, in spyder
    cur2.execute('select count(*) from People_Inf where Name_Url=?', (people_list,))
OperationalError: unable to open database file
2016-07-15 15:07:11,830 - __main__ - DEBUG - there is a error
Traceback (most recent call last):
  File "spyder.py", line 50, in spyder
    cur2.execute('select count(*) from People_Inf where Name_Url=?', (people_list,))
OperationalError: unable to open database file
2016-07-15 15:07:11,901 - __main__ - DEBUG - there is a error
Traceback (most recent call last):
  File "spyder.py", line 50, in spyder
    cur2.execute('select count(*) from People_Inf where Name_Url=?', (people_list,))
OperationalError: unable to open database file
2016-07-15 15:07:11,975 - __main__ - DEBUG - there is a error
Traceback (most recent call last):
  File "spyder.py", line 50, in spyder
    cur2.execute('select count(*) from People_Inf where Name_Url=?', (people_list,))
OperationalError: unable to open database file
2016-07-15 15:07:12,042 - __main__ - DEBUG - there is a error
Traceback (most recent call last):
  File "spyder.py", line 50, in spyder
    cur2.execute('select count(*) from People_Inf where Name_Url=?', (people_list,))
OperationalError: unable to open database file
2016-07-15 15:07:12,111 - __main__ - DEBUG - there is a error
Traceback (most recent call last):
  File "spyder.py", line 50, in spyder
    cur2.execute('select count(*) from People_Inf where Name_Url=?', (people_list,))
OperationalError: unable to open database file
2016-07-15 15:07:12,185 - __main__ - DEBUG - there is a error
Traceback (most recent call last):
  File "spyder.py", line 50, in spyder
    cur2.execute('select count(*) from People_Inf where Name_Url=?', (people_list,))
OperationalError: unable to open database file
2016-07-15 15:07:12,257 - __main__ - DEBUG - there is a error
Traceback (most recent call last):
  File "spyder.py", line 50, in spyder
    cur2.execute('select count(*) from People_Inf where Name_Url=?', (people_list,))
OperationalError: unable to open database file
2016-07-15 15:07:12,357 - __main__ - DEBUG - there is a error
Traceback (most recent call last):
  File "spyder.py", line 50, in spyder
    cur2.execute('select count(*) from People_Inf where Name_Url=?', (people_list,))
OperationalError: unable to open database file
2016-07-15 15:07:12,437 - __main__ - DEBUG - there is a error
Traceback (most recent call last):
  File "spyder.py", line 50, in spyder
    cur2.execute('select count(*) from People_Inf where Name_Url=?', (people_list,))
OperationalError: unable to open database file
2016-07-15 15:07:12,524 - __main__ - DEBUG - there is a error
Traceback (most recent call last):
  File "spyder.py", line 50, in spyder
    cur2.execute('select count(*) from People_Inf where Name_Url=?', (people_list,))
OperationalError: unable to open database file
2016-07-15 15:07:12,604 - __main__ - DEBUG - there is a error
Traceback (most recent call last):
  File "spyder.py", line 50, in spyder
    cur2.execute('select count(*) from People_Inf where Name_Url=?', (people_list,))
OperationalError: unable to open database file
2016-07-15 15:07:12,704 - __main__ - DEBUG - there is a error
Traceback (most recent call last):
  File "spyder.py", line 50, in spyder
    cur2.execute('select count(*) from People_Inf where Name_Url=?', (people_list,))
OperationalError: unable to open database file
2016-07-15 15:07:12,777 - __main__ - DEBUG - there is a error
Traceback (most recent call last):
  File "spyder.py", line 50, in spyder
    cur2.execute('select count(*) from People_Inf where Name_Url=?', (people_list,))
OperationalError: unable to open database file
2016-07-15 15:07:12,861 - __main__ - DEBUG - there is a error
Traceback (most recent call last):
  File "spyder.py", line 50, in spyder
    cur2.execute('select count(*) from People_Inf where Name_Url=?', (people_list,))
OperationalError: unable to open database file
2016-07-15 15:07:12,931 - __main__ - DEBUG - there is a error
Traceback (most recent call last):
  File "spyder.py", line 50, in spyder
    cur2.execute('select count(*) from People_Inf where Name_Url=?', (people_list,))
OperationalError: unable to open database file
2016-07-15 15:07:13,018 - __main__ - DEBUG - there is a error
Traceback (most recent call last):
  File "spyder.py", line 50, in spyder
    cur2.execute('select count(*) from People_Inf where Name_Url=?', (people_list,))
OperationalError: unable to open database file
2016-07-15 15:07:13,085 - __main__ - DEBUG - there is a error
Traceback (most recent call last):
  File "spyder.py", line 50, in spyder
    cur2.execute('select count(*) from People_Inf where Name_Url=?', (people_list,))
OperationalError: unable to open database file
2016-07-15 15:07:13,182 - __main__ - DEBUG - there is a error
Traceback (most recent call last):
  File "spyder.py", line 50, in spyder
    cur2.execute('select count(*) from People_Inf where Name_Url=?', (people_list,))
OperationalError: unable to open database file
2016-07-15 15:07:13,268 - __main__ - DEBUG - there is a error
Traceback (most recent call last):
  File "spyder.py", line 50, in spyder
    cur2.execute('select count(*) from People_Inf where Name_Url=?', (people_list,))
OperationalError: unable to open database file
2016-07-15 15:07:13,386 - __main__ - DEBUG - there is a error
Traceback (most recent call last):
  File "spyder.py", line 50, in spyder
    cur2.execute('select count(*) from People_Inf where Name_Url=?', (people_list,))
OperationalError: unable to open database file
2016-07-15 15:07:13,477 - __main__ - DEBUG - there is a error
Traceback (most recent call last):
  File "spyder.py", line 50, in spyder
    cur2.execute('select count(*) from People_Inf where Name_Url=?', (people_list,))
OperationalError: unable to open database file
2016-07-15 15:07:13,544 - __main__ - DEBUG - there is a error
Traceback (most recent call last):
  File "spyder.py", line 50, in spyder
    cur2.execute('select count(*) from People_Inf where Name_Url=?', (people_list,))
OperationalError: unable to open database file
2016-07-15 15:07:13,613 - __main__ - DEBUG - there is a error
Traceback (most recent call last):
  File "spyder.py", line 50, in spyder
    cur2.execute('select count(*) from People_Inf where Name_Url=?', (people_list,))
OperationalError: unable to open database file
2016-07-15 15:07:13,682 - __main__ - DEBUG - there is a error
Traceback (most recent call last):
  File "spyder.py", line 50, in spyder
    cur2.execute('select count(*) from People_Inf where Name_Url=?', (people_list,))
OperationalError: unable to open database file
2016-07-15 15:07:13,751 - __main__ - DEBUG - there is a error
Traceback (most recent call last):
  File "spyder.py", line 50, in spyder
    cur2.execute('select count(*) from People_Inf where Name_Url=?', (people_list,))
OperationalError: unable to open database file
2016-07-15 15:07:13,847 - __main__ - DEBUG - there is a error
Traceback (most recent call last):
  File "spyder.py", line 50, in spyder
    cur2.execute('select count(*) from People_Inf where Name_Url=?', (people_list,))
OperationalError: unable to open database file
2016-07-15 15:07:13,932 - __main__ - DEBUG - there is a error
Traceback (most recent call last):
  File "spyder.py", line 50, in spyder
    cur2.execute('select count(*) from People_Inf where Name_Url=?', (people_list,))
OperationalError: unable to open database file
2016-07-15 15:07:14,000 - __main__ - DEBUG - there is a error
Traceback (most recent call last):
  File "spyder.py", line 50, in spyder
    cur2.execute('select count(*) from People_Inf where Name_Url=?', (people_list,))
OperationalError: unable to open database file
2016-07-15 15:07:14,067 - __main__ - DEBUG - there is a error
Traceback (most recent call last):
  File "spyder.py", line 50, in spyder
    cur2.execute('select count(*) from People_Inf where Name_Url=?', (people_list,))
OperationalError: unable to open database file
2016-07-15 15:07:14,142 - __main__ - DEBUG - there is a error
Traceback (most recent call last):
  File "spyder.py", line 50, in spyder
    cur2.execute('select count(*) from People_Inf where Name_Url=?', (people_list,))
OperationalError: unable to open database file
2016-07-15 15:07:14,212 - __main__ - DEBUG - there is a error
Traceback (most recent call last):
  File "spyder.py", line 50, in spyder
    cur2.execute('select count(*) from People_Inf where Name_Url=?', (people_list,))
OperationalError: unable to open database file
2016-07-15 15:07:14,307 - __main__ - DEBUG - there is a error
Traceback (most recent call last):
  File "spyder.py", line 50, in spyder
    cur2.execute('select count(*) from People_Inf where Name_Url=?', (people_list,))
OperationalError: unable to open database file
2016-07-15 15:07:14,402 - __main__ - DEBUG - there is a error
Traceback (most recent call last):
  File "spyder.py", line 50, in spyder
    cur2.execute('select count(*) from People_Inf where Name_Url=?', (people_list,))
OperationalError: unable to open database file
2016-07-15 15:07:14,482 - __main__ - DEBUG - there is a error
Traceback (most recent call last):
  File "spyder.py", line 50, in spyder
    cur2.execute('select count(*) from People_Inf where Name_Url=?', (people_list,))
OperationalError: unable to open database file
2016-07-15 15:07:14,560 - __main__ - DEBUG - there is a error
Traceback (most recent call last):
  File "spyder.py", line 50, in spyder
    cur2.execute('select count(*) from People_Inf where Name_Url=?', (people_list,))
OperationalError: unable to open database file
2016-07-15 15:07:14,633 - __main__ - DEBUG - there is a error
Traceback (most recent call last):
  File "spyder.py", line 50, in spyder
    cur2.execute('select count(*) from People_Inf where Name_Url=?', (people_list,))
OperationalError: unable to open database file
2016-07-15 15:07:14,695 - __main__ - DEBUG - there is a error
Traceback (most recent call last):
  File "spyder.py", line 50, in spyder
    cur2.execute('select count(*) from People_Inf where Name_Url=?', (people_list,))
OperationalError: unable to open database file
2016-07-15 15:07:14,766 - __main__ - DEBUG - there is a error
Traceback (most recent call last):
  File "spyder.py", line 50, in spyder
    cur2.execute('select count(*) from People_Inf where Name_Url=?', (people_list,))
OperationalError: unable to open database file
2016-07-15 15:07:14,833 - __main__ - DEBUG - there is a error
Traceback (most recent call last):
  File "spyder.py", line 50, in spyder
    cur2.execute('select count(*) from People_Inf where Name_Url=?', (people_list,))
OperationalError: unable to open database file
2016-07-15 15:07:14,894 - __main__ - DEBUG - there is a error
Traceback (most recent call last):
  File "spyder.py", line 50, in spyder
    cur2.execute('select count(*) from People_Inf where Name_Url=?', (people_list,))
OperationalError: unable to open database file
2016-07-15 15:07:14,986 - __main__ - DEBUG - there is a error
Traceback (most recent call last):
  File "spyder.py", line 50, in spyder
    cur2.execute('select count(*) from People_Inf where Name_Url=?', (people_list,))
OperationalError: unable to open database file
2016-07-15 15:07:15,055 - __main__ - DEBUG - there is a error
Traceback (most recent call last):
  File "spyder.py", line 50, in spyder
    cur2.execute('select count(*) from People_Inf where Name_Url=?', (people_list,))
OperationalError: unable to open database file
2016-07-15 15:07:15,164 - __main__ - DEBUG - there is a error
Traceback (most recent call last):
  File "spyder.py", line 50, in spyder
    cur2.execute('select count(*) from People_Inf where Name_Url=?', (people_list,))
OperationalError: unable to open database file
2016-07-15 15:07:15,228 - __main__ - DEBUG - there is a error
Traceback (most recent call last):
  File "spyder.py", line 50, in spyder
    cur2.execute('select count(*) from People_Inf where Name_Url=?', (people_list,))
OperationalError: unable to open database file
2016-07-15 15:07:15,292 - __main__ - DEBUG - there is a error
Traceback (most recent call last):
  File "spyder.py", line 50, in spyder
    cur2.execute('select count(*) from People_Inf where Name_Url=?', (people_list,))
OperationalError: unable to open database file
2016-07-15 15:07:15,357 - __main__ - DEBUG - there is a error
Traceback (most recent call last):
  File "spyder.py", line 50, in spyder
    cur2.execute('select count(*) from People_Inf where Name_Url=?', (people_list,))
OperationalError: unable to open database file
2016-07-15 15:07:15,420 - __main__ - DEBUG - there is a error
Traceback (most recent call last):
  File "spyder.py", line 50, in spyder
    cur2.execute('select count(*) from People_Inf where Name_Url=?', (people_list,))
OperationalError: unable to open database file
2016-07-15 15:07:15,496 - __main__ - DEBUG - there is a error
Traceback (most recent call last):
  File "spyder.py", line 50, in spyder
    cur2.execute('select count(*) from People_Inf where Name_Url=?', (people_list,))
OperationalError: unable to open database file
2016-07-15 15:07:15,567 - __main__ - DEBUG - there is a error
Traceback (most recent call last):
  File "spyder.py", line 50, in spyder
    cur2.execute('select count(*) from People_Inf where Name_Url=?', (people_list,))
OperationalError: unable to open database file
2016-07-15 15:07:15,630 - __main__ - DEBUG - there is a error
Traceback (most recent call last):
  File "spyder.py", line 50, in spyder
    cur2.execute('select count(*) from People_Inf where Name_Url=?', (people_list,))
OperationalError: unable to open database file
2016-07-15 15:07:15,694 - __main__ - DEBUG - there is a error
Traceback (most recent call last):
  File "spyder.py", line 50, in spyder
    cur2.execute('select count(*) from People_Inf where Name_Url=?', (people_list,))
OperationalError: unable to open database file
2016-07-15 15:07:15,757 - __main__ - DEBUG - there is a error
Traceback (most recent call last):
  File "spyder.py", line 50, in spyder
    cur2.execute('select count(*) from People_Inf where Name_Url=?', (people_list,))
OperationalError: unable to open database file
2016-07-15 15:07:15,820 - __main__ - DEBUG - there is a error
Traceback (most recent call last):
  File "spyder.py", line 50, in spyder
    cur2.execute('select count(*) from People_Inf where Name_Url=?', (people_list,))
OperationalError: unable to open database file
2016-07-15 15:07:15,883 - __main__ - DEBUG - there is a error
Traceback (most recent call last):
  File "spyder.py", line 50, in spyder
    cur2.execute('select count(*) from People_Inf where Name_Url=?', (people_list,))
OperationalError: unable to open database file
2016-07-15 15:07:15,960 - __main__ - DEBUG - there is a error
Traceback (most recent call last):
  File "spyder.py", line 50, in spyder
    cur2.execute('select count(*) from People_Inf where Name_Url=?', (people_list,))
OperationalError: unable to open database file
2016-07-15 15:07:16,022 - __main__ - DEBUG - there is a error
Traceback (most recent call last):
  File "spyder.py", line 50, in spyder
    cur2.execute('select count(*) from People_Inf where Name_Url=?', (people_list,))
OperationalError: unable to open database file
2016-07-15 15:07:16,114 - __main__ - DEBUG - there is a error
Traceback (most recent call last):
  File "spyder.py", line 50, in spyder
    cur2.execute('select count(*) from People_Inf where Name_Url=?', (people_list,))
OperationalError: unable to open database file
2016-07-15 15:07:16,180 - __main__ - DEBUG - there is a error
Traceback (most recent call last):
  File "spyder.py", line 50, in spyder
    cur2.execute('select count(*) from People_Inf where Name_Url=?', (people_list,))
OperationalError: unable to open database file
2016-07-15 15:07:16,243 - __main__ - DEBUG - there is a error
Traceback (most recent call last):
  File "spyder.py", line 50, in spyder
    cur2.execute('select count(*) from People_Inf where Name_Url=?', (people_list,))
OperationalError: unable to open database file
2016-07-15 15:07:16,315 - __main__ - DEBUG - there is a error
Traceback (most recent call last):
  File "spyder.py", line 50, in spyder
    cur2.execute('select count(*) from People_Inf where Name_Url=?', (people_list,))
OperationalError: unable to open database file
2016-07-15 15:07:16,419 - __main__ - DEBUG - there is a error
Traceback (most recent call last):
  File "spyder.py", line 50, in spyder
    cur2.execute('select count(*) from People_Inf where Name_Url=?', (people_list,))
OperationalError: unable to open database file
2016-07-15 15:07:16,567 - __main__ - DEBUG - there is a error
Traceback (most recent call last):
  File "spyder.py", line 50, in spyder
    cur2.execute('select count(*) from People_Inf where Name_Url=?', (people_list,))
OperationalError: unable to open database file
2016-07-15 15:07:16,665 - __main__ - DEBUG - there is a error
Traceback (most recent call last):
  File "spyder.py", line 50, in spyder
    cur2.execute('select count(*) from People_Inf where Name_Url=?', (people_list,))
OperationalError: unable to open database file
2016-07-15 15:07:16,734 - __main__ - DEBUG - there is a error
Traceback (most recent call last):
  File "spyder.py", line 50, in spyder
    cur2.execute('select count(*) from People_Inf where Name_Url=?', (people_list,))
OperationalError: unable to open database file
2016-07-15 15:07:16,805 - __main__ - DEBUG - there is a error
Traceback (most recent call last):
  File "spyder.py", line 50, in spyder
    cur2.execute('select count(*) from People_Inf where Name_Url=?', (people_list,))
OperationalError: unable to open database file
2016-07-15 15:07:16,878 - __main__ - DEBUG - there is a error
Traceback (most recent call last):
  File "spyder.py", line 50, in spyder
    cur2.execute('select count(*) from People_Inf where Name_Url=?', (people_list,))
OperationalError: unable to open database file
2016-07-15 15:07:16,946 - __main__ - DEBUG - there is a error
Traceback (most recent call last):
  File "spyder.py", line 50, in spyder
    cur2.execute('select count(*) from People_Inf where Name_Url=?', (people_list,))
OperationalError: unable to open database file
2016-07-15 15:07:17,011 - __main__ - DEBUG - there is a error
Traceback (most recent call last):
  File "spyder.py", line 50, in spyder
    cur2.execute('select count(*) from People_Inf where Name_Url=?', (people_list,))
OperationalError: unable to open database file
2016-07-15 15:07:17,075 - __main__ - DEBUG - there is a error
Traceback (most recent call last):
  File "spyder.py", line 50, in spyder
    cur2.execute('select count(*) from People_Inf where Name_Url=?', (people_list,))
OperationalError: unable to open database file
2016-07-15 15:07:17,139 - __main__ - DEBUG - there is a error
Traceback (most recent call last):
  File "spyder.py", line 50, in spyder
    cur2.execute('select count(*) from People_Inf where Name_Url=?', (people_list,))
OperationalError: unable to open database file
2016-07-15 15:07:17,205 - __main__ - DEBUG - there is a error
Traceback (most recent call last):
  File "spyder.py", line 50, in spyder
    cur2.execute('select count(*) from People_Inf where Name_Url=?', (people_list,))
OperationalError: unable to open database file
2016-07-15 15:07:17,280 - __main__ - DEBUG - there is a error
Traceback (most recent call last):
  File "spyder.py", line 50, in spyder
    cur2.execute('select count(*) from People_Inf where Name_Url=?', (people_list,))
OperationalError: unable to open database file
2016-07-15 15:07:17,356 - __main__ - DEBUG - there is a error
Traceback (most recent call last):
  File "spyder.py", line 50, in spyder
    cur2.execute('select count(*) from People_Inf where Name_Url=?', (people_list,))
OperationalError: unable to open database file
2016-07-15 15:07:17,428 - __main__ - DEBUG - there is a error
Traceback (most recent call last):
  File "spyder.py", line 50, in spyder
    cur2.execute('select count(*) from People_Inf where Name_Url=?', (people_list,))
OperationalError: unable to open database file
2016-07-15 15:07:17,534 - __main__ - DEBUG - there is a error
Traceback (most recent call last):
  File "spyder.py", line 50, in spyder
    cur2.execute('select count(*) from People_Inf where Name_Url=?', (people_list,))
OperationalError: unable to open database file
2016-07-15 15:07:17,641 - __main__ - DEBUG - there is a error
Traceback (most recent call last):
  File "spyder.py", line 50, in spyder
    cur2.execute('select count(*) from People_Inf where Name_Url=?', (people_list,))
OperationalError: unable to open database file
2016-07-15 15:07:17,712 - __main__ - DEBUG - there is a error
Traceback (most recent call last):
  File "spyder.py", line 50, in spyder
    cur2.execute('select count(*) from People_Inf where Name_Url=?', (people_list,))
OperationalError: unable to open database file
2016-07-15 15:07:17,786 - __main__ - DEBUG - there is a error
Traceback (most recent call last):
  File "spyder.py", line 50, in spyder
    cur2.execute('select count(*) from People_Inf where Name_Url=?', (people_list,))
OperationalError: unable to open database file
2016-07-15 15:07:17,863 - __main__ - DEBUG - there is a error
Traceback (most recent call last):
  File "spyder.py", line 50, in spyder
    cur2.execute('select count(*) from People_Inf where Name_Url=?', (people_list,))
OperationalError: unable to open database file
2016-07-15 15:07:17,928 - __main__ - DEBUG - there is a error
Traceback (most recent call last):
  File "spyder.py", line 50, in spyder
    cur2.execute('select count(*) from People_Inf where Name_Url=?', (people_list,))
OperationalError: unable to open database file
2016-07-15 15:07:17,994 - __main__ - DEBUG - there is a error
Traceback (most recent call last):
  File "spyder.py", line 50, in spyder
    cur2.execute('select count(*) from People_Inf where Name_Url=?', (people_list,))
OperationalError: unable to open database file
2016-07-15 15:07:18,177 - __main__ - DEBUG - there is a error
Traceback (most recent call last):
  File "spyder.py", line 50, in spyder
    cur2.execute('select count(*) from People_Inf where Name_Url=?', (people_list,))
OperationalError: unable to open database file
2016-07-15 15:07:18,259 - __main__ - DEBUG - there is a error
Traceback (most recent call last):
  File "spyder.py", line 50, in spyder
    cur2.execute('select count(*) from People_Inf where Name_Url=?', (people_list,))
OperationalError: unable to open database file
2016-07-15 15:07:18,323 - __main__ - DEBUG - there is a error
Traceback (most recent call last):
  File "spyder.py", line 50, in spyder
    cur2.execute('select count(*) from People_Inf where Name_Url=?', (people_list,))
OperationalError: unable to open database file
2016-07-15 15:07:18,387 - __main__ - DEBUG - there is a error
Traceback (most recent call last):
  File "spyder.py", line 50, in spyder
    cur2.execute('select count(*) from People_Inf where Name_Url=?', (people_list,))
OperationalError: unable to open database file
2016-07-15 15:07:18,483 - __main__ - DEBUG - there is a error
Traceback (most recent call last):
  File "spyder.py", line 50, in spyder
    cur2.execute('select count(*) from People_Inf where Name_Url=?', (people_list,))
OperationalError: unable to open database file
2016-07-15 15:07:18,547 - __main__ - DEBUG - there is a error
Traceback (most recent call last):
  File "spyder.py", line 50, in spyder
    cur2.execute('select count(*) from People_Inf where Name_Url=?', (people_list,))
OperationalError: unable to open database file
2016-07-15 15:07:18,613 - __main__ - DEBUG - there is a error
Traceback (most recent call last):
  File "spyder.py", line 50, in spyder
    cur2.execute('select count(*) from People_Inf where Name_Url=?', (people_list,))
OperationalError: unable to open database file
2016-07-15 15:07:18,680 - __main__ - DEBUG - there is a error
Traceback (most recent call last):
  File "spyder.py", line 50, in spyder
    cur2.execute('select count(*) from People_Inf where Name_Url=?', (people_list,))
OperationalError: unable to open database file
2016-07-15 15:07:18,753 - __main__ - DEBUG - there is a error
Traceback (most recent call last):
  File "spyder.py", line 50, in spyder
    cur2.execute('select count(*) from People_Inf where Name_Url=?', (people_list,))
OperationalError: unable to open database file
2016-07-15 15:07:18,833 - __main__ - DEBUG - there is a error
Traceback (most recent call last):
  File "spyder.py", line 50, in spyder
    cur2.execute('select count(*) from People_Inf where Name_Url=?', (people_list,))
OperationalError: unable to open database file
2016-07-15 15:07:18,899 - __main__ - DEBUG - there is a error
Traceback (most recent call last):
  File "spyder.py", line 50, in spyder
    cur2.execute('select count(*) from People_Inf where Name_Url=?', (people_list,))
OperationalError: unable to open database file
2016-07-15 15:07:18,964 - __main__ - DEBUG - there is a error
Traceback (most recent call last):
  File "spyder.py", line 50, in spyder
    cur2.execute('select count(*) from People_Inf where Name_Url=?', (people_list,))
OperationalError: unable to open database file
2016-07-15 15:07:19,043 - __main__ - DEBUG - there is a error
Traceback (most recent call last):
  File "spyder.py", line 50, in spyder
    cur2.execute('select count(*) from People_Inf where Name_Url=?', (people_list,))
OperationalError: unable to open database file
2016-07-15 15:07:19,108 - __main__ - DEBUG - there is a error
Traceback (most recent call last):
  File "spyder.py", line 50, in spyder
    cur2.execute('select count(*) from People_Inf where Name_Url=?', (people_list,))
OperationalError: unable to open database file
2016-07-15 15:07:19,172 - __main__ - DEBUG - there is a error
Traceback (most recent call last):
  File "spyder.py", line 50, in spyder
    cur2.execute('select count(*) from People_Inf where Name_Url=?', (people_list,))
OperationalError: unable to open database file
2016-07-15 15:07:19,237 - __main__ - DEBUG - there is a error
Traceback (most recent call last):
  File "spyder.py", line 50, in spyder
    cur2.execute('select count(*) from People_Inf where Name_Url=?', (people_list,))
OperationalError: unable to open database file
2016-07-15 15:07:19,312 - __main__ - DEBUG - there is a error
Traceback (most recent call last):
  File "spyder.py", line 50, in spyder
    cur2.execute('select count(*) from People_Inf where Name_Url=?', (people_list,))
OperationalError: unable to open database file
2016-07-15 15:07:19,376 - __main__ - DEBUG - there is a error
Traceback (most recent call last):
  File "spyder.py", line 50, in spyder
    cur2.execute('select count(*) from People_Inf where Name_Url=?', (people_list,))
OperationalError: unable to open database file
2016-07-15 15:07:19,439 - __main__ - DEBUG - there is a error
Traceback (most recent call last):
  File "spyder.py", line 50, in spyder
    cur2.execute('select count(*) from People_Inf where Name_Url=?', (people_list,))
OperationalError: unable to open database file
2016-07-15 15:07:19,506 - __main__ - DEBUG - there is a error
Traceback (most recent call last):
  File "spyder.py", line 50, in spyder
    cur2.execute('select count(*) from People_Inf where Name_Url=?', (people_list,))
OperationalError: unable to open database file
2016-07-15 15:07:19,569 - __main__ - DEBUG - there is a error
Traceback (most recent call last):
  File "spyder.py", line 50, in spyder
    cur2.execute('select count(*) from People_Inf where Name_Url=?', (people_list,))
OperationalError: unable to open database file
2016-07-15 15:07:19,661 - __main__ - DEBUG - there is a error
Traceback (most recent call last):
  File "spyder.py", line 50, in spyder
    cur2.execute('select count(*) from People_Inf where Name_Url=?', (people_list,))
OperationalError: unable to open database file
2016-07-15 15:07:19,726 - __main__ - DEBUG - there is a error
Traceback (most recent call last):
  File "spyder.py", line 50, in spyder
    cur2.execute('select count(*) from People_Inf where Name_Url=?', (people_list,))
OperationalError: unable to open database file
2016-07-15 15:07:19,804 - __main__ - DEBUG - there is a error
Traceback (most recent call last):
  File "spyder.py", line 50, in spyder
    cur2.execute('select count(*) from People_Inf where Name_Url=?', (people_list,))
OperationalError: unable to open database file
2016-07-15 15:07:19,872 - __main__ - DEBUG - there is a error
Traceback (most recent call last):
  File "spyder.py", line 50, in spyder
    cur2.execute('select count(*) from People_Inf where Name_Url=?', (people_list,))
OperationalError: unable to open database file
2016-07-15 15:07:19,949 - __main__ - DEBUG - there is a error
Traceback (most recent call last):
  File "spyder.py", line 50, in spyder
    cur2.execute('select count(*) from People_Inf where Name_Url=?', (people_list,))
OperationalError: unable to open database file
2016-07-15 15:07:20,014 - __main__ - DEBUG - there is a error
Traceback (most recent call last):
  File "spyder.py", line 50, in spyder
    cur2.execute('select count(*) from People_Inf where Name_Url=?', (people_list,))
OperationalError: unable to open database file
2016-07-15 15:07:20,080 - __main__ - DEBUG - there is a error
Traceback (most recent call last):
  File "spyder.py", line 50, in spyder
    cur2.execute('select count(*) from People_Inf where Name_Url=?', (people_list,))
OperationalError: unable to open database file
2016-07-15 15:07:20,145 - __main__ - DEBUG - there is a error
Traceback (most recent call last):
  File "spyder.py", line 50, in spyder
    cur2.execute('select count(*) from People_Inf where Name_Url=?', (people_list,))
OperationalError: unable to open database file
2016-07-15 15:07:20,222 - __main__ - DEBUG - there is a error
Traceback (most recent call last):
  File "spyder.py", line 50, in spyder
    cur2.execute('select count(*) from People_Inf where Name_Url=?', (people_list,))
OperationalError: unable to open database file
2016-07-15 15:07:20,287 - __main__ - DEBUG - there is a error
Traceback (most recent call last):
  File "spyder.py", line 50, in spyder
    cur2.execute('select count(*) from People_Inf where Name_Url=?', (people_list,))
OperationalError: unable to open database file
2016-07-15 15:07:20,352 - __main__ - DEBUG - there is a error
Traceback (most recent call last):
  File "spyder.py", line 50, in spyder
    cur2.execute('select count(*) from People_Inf where Name_Url=?', (people_list,))
OperationalError: unable to open database file
2016-07-15 15:07:20,428 - __main__ - DEBUG - there is a error
Traceback (most recent call last):
  File "spyder.py", line 50, in spyder
    cur2.execute('select count(*) from People_Inf where Name_Url=?', (people_list,))
OperationalError: unable to open database file
2016-07-15 15:07:20,493 - __main__ - DEBUG - there is a error
Traceback (most recent call last):
  File "spyder.py", line 50, in spyder
    cur2.execute('select count(*) from People_Inf where Name_Url=?', (people_list,))
OperationalError: unable to open database file
2016-07-15 15:07:20,567 - __main__ - DEBUG - there is a error
Traceback (most recent call last):
  File "spyder.py", line 50, in spyder
    cur2.execute('select count(*) from People_Inf where Name_Url=?', (people_list,))
OperationalError: unable to open database file
2016-07-15 15:07:20,632 - __main__ - DEBUG - there is a error
Traceback (most recent call last):
  File "spyder.py", line 50, in spyder
    cur2.execute('select count(*) from People_Inf where Name_Url=?', (people_list,))
OperationalError: unable to open database file
2016-07-15 15:07:20,706 - __main__ - DEBUG - there is a error
Traceback (most recent call last):
  File "spyder.py", line 50, in spyder
    cur2.execute('select count(*) from People_Inf where Name_Url=?', (people_list,))
OperationalError: unable to open database file
2016-07-15 15:07:20,781 - __main__ - DEBUG - there is a error
Traceback (most recent call last):
  File "spyder.py", line 50, in spyder
    cur2.execute('select count(*) from People_Inf where Name_Url=?', (people_list,))
OperationalError: unable to open database file
2016-07-15 15:07:20,846 - __main__ - DEBUG - there is a error
Traceback (most recent call last):
  File "spyder.py", line 50, in spyder
    cur2.execute('select count(*) from People_Inf where Name_Url=?', (people_list,))
OperationalError: unable to open database file
2016-07-15 15:07:20,920 - __main__ - DEBUG - there is a error
Traceback (most recent call last):
  File "spyder.py", line 50, in spyder
    cur2.execute('select count(*) from People_Inf where Name_Url=?', (people_list,))
OperationalError: unable to open database file
2016-07-15 15:07:20,990 - __main__ - DEBUG - there is a error
Traceback (most recent call last):
  File "spyder.py", line 50, in spyder
    cur2.execute('select count(*) from People_Inf where Name_Url=?', (people_list,))
OperationalError: unable to open database file
2016-07-15 15:07:21,089 - __main__ - DEBUG - there is a error
Traceback (most recent call last):
  File "spyder.py", line 50, in spyder
    cur2.execute('select count(*) from People_Inf where Name_Url=?', (people_list,))
OperationalError: unable to open database file
2016-07-15 15:07:21,171 - __main__ - DEBUG - there is a error
Traceback (most recent call last):
  File "spyder.py", line 50, in spyder
    cur2.execute('select count(*) from People_Inf where Name_Url=?', (people_list,))
OperationalError: unable to open database file
2016-07-15 15:07:21,241 - __main__ - DEBUG - there is a error
Traceback (most recent call last):
  File "spyder.py", line 50, in spyder
    cur2.execute('select count(*) from People_Inf where Name_Url=?', (people_list,))
OperationalError: unable to open database file
2016-07-15 15:07:21,304 - __main__ - DEBUG - there is a error
Traceback (most recent call last):
  File "spyder.py", line 50, in spyder
    cur2.execute('select count(*) from People_Inf where Name_Url=?', (people_list,))
OperationalError: unable to open database file
2016-07-15 15:07:21,375 - __main__ - DEBUG - there is a error
Traceback (most recent call last):
  File "spyder.py", line 50, in spyder
    cur2.execute('select count(*) from People_Inf where Name_Url=?', (people_list,))
OperationalError: unable to open database file
2016-07-15 15:07:21,470 - __main__ - DEBUG - there is a error
Traceback (most recent call last):
  File "spyder.py", line 50, in spyder
    cur2.execute('select count(*) from People_Inf where Name_Url=?', (people_list,))
OperationalError: unable to open database file
2016-07-15 15:07:21,545 - __main__ - DEBUG - there is a error
Traceback (most recent call last):
  File "spyder.py", line 50, in spyder
    cur2.execute('select count(*) from People_Inf where Name_Url=?', (people_list,))
OperationalError: unable to open database file
2016-07-15 15:07:21,623 - __main__ - DEBUG - there is a error
Traceback (most recent call last):
  File "spyder.py", line 50, in spyder
    cur2.execute('select count(*) from People_Inf where Name_Url=?', (people_list,))
OperationalError: unable to open database file
2016-07-15 15:07:21,690 - __main__ - DEBUG - there is a error
Traceback (most recent call last):
  File "spyder.py", line 50, in spyder
    cur2.execute('select count(*) from People_Inf where Name_Url=?', (people_list,))
OperationalError: unable to open database file
2016-07-15 15:07:21,764 - __main__ - DEBUG - there is a error
Traceback (most recent call last):
  File "spyder.py", line 50, in spyder
    cur2.execute('select count(*) from People_Inf where Name_Url=?', (people_list,))
OperationalError: unable to open database file
2016-07-15 15:07:21,856 - __main__ - DEBUG - there is a error
Traceback (most recent call last):
  File "spyder.py", line 50, in spyder
    cur2.execute('select count(*) from People_Inf where Name_Url=?', (people_list,))
OperationalError: unable to open database file
2016-07-15 15:07:21,938 - __main__ - DEBUG - there is a error
Traceback (most recent call last):
  File "spyder.py", line 50, in spyder
    cur2.execute('select count(*) from People_Inf where Name_Url=?', (people_list,))
OperationalError: unable to open database file
2016-07-15 15:07:22,007 - __main__ - DEBUG - there is a error
Traceback (most recent call last):
  File "spyder.py", line 50, in spyder
    cur2.execute('select count(*) from People_Inf where Name_Url=?', (people_list,))
OperationalError: unable to open database file
2016-07-15 15:07:22,089 - __main__ - DEBUG - there is a error
Traceback (most recent call last):
  File "spyder.py", line 50, in spyder
    cur2.execute('select count(*) from People_Inf where Name_Url=?', (people_list,))
OperationalError: unable to open database file
2016-07-15 15:07:22,188 - __main__ - DEBUG - there is a error
Traceback (most recent call last):
  File "spyder.py", line 50, in spyder
    cur2.execute('select count(*) from People_Inf where Name_Url=?', (people_list,))
OperationalError: unable to open database file
2016-07-15 15:07:22,260 - __main__ - DEBUG - there is a error
Traceback (most recent call last):
  File "spyder.py", line 50, in spyder
    cur2.execute('select count(*) from People_Inf where Name_Url=?', (people_list,))
OperationalError: unable to open database file
2016-07-15 15:07:22,382 - __main__ - DEBUG - there is a error
Traceback (most recent call last):
  File "spyder.py", line 50, in spyder
    cur2.execute('select count(*) from People_Inf where Name_Url=?', (people_list,))
OperationalError: unable to open database file
2016-07-15 15:07:22,459 - __main__ - DEBUG - there is a error
Traceback (most recent call last):
  File "spyder.py", line 50, in spyder
    cur2.execute('select count(*) from People_Inf where Name_Url=?', (people_list,))
OperationalError: unable to open database file
2016-07-15 15:07:22,531 - __main__ - DEBUG - there is a error
Traceback (most recent call last):
  File "spyder.py", line 50, in spyder
    cur2.execute('select count(*) from People_Inf where Name_Url=?', (people_list,))
OperationalError: unable to open database file
2016-07-15 15:07:22,611 - __main__ - DEBUG - there is a error
Traceback (most recent call last):
  File "spyder.py", line 50, in spyder
    cur2.execute('select count(*) from People_Inf where Name_Url=?', (people_list,))
OperationalError: unable to open database file
2016-07-15 15:07:22,679 - __main__ - DEBUG - there is a error
Traceback (most recent call last):
  File "spyder.py", line 50, in spyder
    cur2.execute('select count(*) from People_Inf where Name_Url=?', (people_list,))
OperationalError: unable to open database file
2016-07-15 15:07:22,746 - __main__ - DEBUG - there is a error
Traceback (most recent call last):
  File "spyder.py", line 50, in spyder
    cur2.execute('select count(*) from People_Inf where Name_Url=?', (people_list,))
OperationalError: unable to open database file
2016-07-15 15:07:22,815 - __main__ - DEBUG - there is a error
Traceback (most recent call last):
  File "spyder.py", line 50, in spyder
    cur2.execute('select count(*) from People_Inf where Name_Url=?', (people_list,))
OperationalError: unable to open database file
2016-07-15 15:07:22,893 - __main__ - DEBUG - there is a error
Traceback (most recent call last):
  File "spyder.py", line 50, in spyder
    cur2.execute('select count(*) from People_Inf where Name_Url=?', (people_list,))
OperationalError: unable to open database file
2016-07-15 15:07:23,104 - __main__ - DEBUG - there is a error
Traceback (most recent call last):
  File "spyder.py", line 50, in spyder
    cur2.execute('select count(*) from People_Inf where Name_Url=?', (people_list,))
OperationalError: unable to open database file
2016-07-15 15:07:23,181 - __main__ - DEBUG - there is a error
Traceback (most recent call last):
  File "spyder.py", line 50, in spyder
    cur2.execute('select count(*) from People_Inf where Name_Url=?', (people_list,))
OperationalError: unable to open database file
2016-07-15 15:07:23,259 - __main__ - DEBUG - there is a error
Traceback (most recent call last):
  File "spyder.py", line 50, in spyder
    cur2.execute('select count(*) from People_Inf where Name_Url=?', (people_list,))
OperationalError: unable to open database file
2016-07-15 15:07:23,328 - __main__ - DEBUG - there is a error
Traceback (most recent call last):
  File "spyder.py", line 50, in spyder
    cur2.execute('select count(*) from People_Inf where Name_Url=?', (people_list,))
OperationalError: unable to open database file
2016-07-15 15:07:23,395 - __main__ - DEBUG - there is a error
Traceback (most recent call last):
  File "spyder.py", line 50, in spyder
    cur2.execute('select count(*) from People_Inf where Name_Url=?', (people_list,))
OperationalError: unable to open database file
2016-07-15 15:07:23,466 - __main__ - DEBUG - there is a error
Traceback (most recent call last):
  File "spyder.py", line 50, in spyder
    cur2.execute('select count(*) from People_Inf where Name_Url=?', (people_list,))
OperationalError: unable to open database file
2016-07-15 15:07:23,598 - __main__ - DEBUG - there is a error
Traceback (most recent call last):
  File "spyder.py", line 50, in spyder
    cur2.execute('select count(*) from People_Inf where Name_Url=?', (people_list,))
OperationalError: unable to open database file
2016-07-15 15:07:23,690 - __main__ - DEBUG - there is a error
Traceback (most recent call last):
  File "spyder.py", line 50, in spyder
    cur2.execute('select count(*) from People_Inf where Name_Url=?', (people_list,))
OperationalError: unable to open database file
2016-07-15 15:07:23,769 - __main__ - DEBUG - there is a error
Traceback (most recent call last):
  File "spyder.py", line 50, in spyder
    cur2.execute('select count(*) from People_Inf where Name_Url=?', (people_list,))
OperationalError: unable to open database file
2016-07-15 15:07:23,841 - __main__ - DEBUG - there is a error
Traceback (most recent call last):
  File "spyder.py", line 50, in spyder
    cur2.execute('select count(*) from People_Inf where Name_Url=?', (people_list,))
OperationalError: unable to open database file
2016-07-15 15:07:23,909 - __main__ - DEBUG - there is a error
Traceback (most recent call last):
  File "spyder.py", line 50, in spyder
    cur2.execute('select count(*) from People_Inf where Name_Url=?', (people_list,))
OperationalError: unable to open database file
2016-07-15 15:07:23,991 - __main__ - DEBUG - there is a error
Traceback (most recent call last):
  File "spyder.py", line 50, in spyder
    cur2.execute('select count(*) from People_Inf where Name_Url=?', (people_list,))
OperationalError: unable to open database file
2016-07-15 15:07:24,064 - __main__ - DEBUG - there is a error
Traceback (most recent call last):
  File "spyder.py", line 50, in spyder
    cur2.execute('select count(*) from People_Inf where Name_Url=?', (people_list,))
OperationalError: unable to open database file
2016-07-15 15:07:24,130 - __main__ - DEBUG - there is a error
Traceback (most recent call last):
  File "spyder.py", line 50, in spyder
    cur2.execute('select count(*) from People_Inf where Name_Url=?', (people_list,))
OperationalError: unable to open database file
2016-07-15 15:07:24,235 - __main__ - DEBUG - there is a error
Traceback (most recent call last):
  File "spyder.py", line 50, in spyder
    cur2.execute('select count(*) from People_Inf where Name_Url=?', (people_list,))
OperationalError: unable to open database file
2016-07-15 15:07:24,304 - __main__ - DEBUG - there is a error
Traceback (most recent call last):
  File "spyder.py", line 50, in spyder
    cur2.execute('select count(*) from People_Inf where Name_Url=?', (people_list,))
OperationalError: unable to open database file
2016-07-15 15:07:24,372 - __main__ - DEBUG - there is a error
Traceback (most recent call last):
  File "spyder.py", line 50, in spyder
    cur2.execute('select count(*) from People_Inf where Name_Url=?', (people_list,))
OperationalError: unable to open database file
2016-07-15 15:07:24,465 - __main__ - DEBUG - there is a error
Traceback (most recent call last):
  File "spyder.py", line 50, in spyder
    cur2.execute('select count(*) from People_Inf where Name_Url=?', (people_list,))
OperationalError: unable to open database file
2016-07-15 15:07:24,546 - __main__ - DEBUG - there is a error
Traceback (most recent call last):
  File "spyder.py", line 50, in spyder
    cur2.execute('select count(*) from People_Inf where Name_Url=?', (people_list,))
OperationalError: unable to open database file
2016-07-15 15:07:24,619 - __main__ - DEBUG - there is a error
Traceback (most recent call last):
  File "spyder.py", line 50, in spyder
    cur2.execute('select count(*) from People_Inf where Name_Url=?', (people_list,))
OperationalError: unable to open database file
2016-07-15 15:07:24,686 - __main__ - DEBUG - there is a error
Traceback (most recent call last):
  File "spyder.py", line 50, in spyder
    cur2.execute('select count(*) from People_Inf where Name_Url=?', (people_list,))
OperationalError: unable to open database file
2016-07-15 15:07:24,761 - __main__ - DEBUG - there is a error
Traceback (most recent call last):
  File "spyder.py", line 50, in spyder
    cur2.execute('select count(*) from People_Inf where Name_Url=?', (people_list,))
OperationalError: unable to open database file
2016-07-15 15:07:24,835 - __main__ - DEBUG - there is a error
Traceback (most recent call last):
  File "spyder.py", line 50, in spyder
    cur2.execute('select count(*) from People_Inf where Name_Url=?', (people_list,))
OperationalError: unable to open database file
2016-07-15 15:07:24,917 - __main__ - DEBUG - there is a error
Traceback (most recent call last):
  File "spyder.py", line 50, in spyder
    cur2.execute('select count(*) from People_Inf where Name_Url=?', (people_list,))
OperationalError: unable to open database file
2016-07-15 15:07:24,987 - __main__ - DEBUG - there is a error
Traceback (most recent call last):
  File "spyder.py", line 50, in spyder
    cur2.execute('select count(*) from People_Inf where Name_Url=?', (people_list,))
OperationalError: unable to open database file
2016-07-15 15:07:25,060 - __main__ - DEBUG - there is a error
Traceback (most recent call last):
  File "spyder.py", line 50, in spyder
    cur2.execute('select count(*) from People_Inf where Name_Url=?', (people_list,))
OperationalError: unable to open database file
2016-07-15 15:07:25,132 - __main__ - DEBUG - there is a error
Traceback (most recent call last):
  File "spyder.py", line 50, in spyder
    cur2.execute('select count(*) from People_Inf where Name_Url=?', (people_list,))
OperationalError: unable to open database file
2016-07-15 15:07:25,215 - __main__ - DEBUG - there is a error
Traceback (most recent call last):
  File "spyder.py", line 50, in spyder
    cur2.execute('select count(*) from People_Inf where Name_Url=?', (people_list,))
OperationalError: unable to open database file
2016-07-15 15:07:25,282 - __main__ - DEBUG - there is a error
Traceback (most recent call last):
  File "spyder.py", line 50, in spyder
    cur2.execute('select count(*) from People_Inf where Name_Url=?', (people_list,))
OperationalError: unable to open database file
2016-07-15 15:07:25,369 - __main__ - DEBUG - there is a error
Traceback (most recent call last):
  File "spyder.py", line 50, in spyder
    cur2.execute('select count(*) from People_Inf where Name_Url=?', (people_list,))
OperationalError: unable to open database file
2016-07-15 15:07:25,436 - __main__ - DEBUG - there is a error
Traceback (most recent call last):
  File "spyder.py", line 50, in spyder
    cur2.execute('select count(*) from People_Inf where Name_Url=?', (people_list,))
OperationalError: unable to open database file
2016-07-15 15:07:25,506 - __main__ - DEBUG - there is a error
Traceback (most recent call last):
  File "spyder.py", line 50, in spyder
    cur2.execute('select count(*) from People_Inf where Name_Url=?', (people_list,))
OperationalError: unable to open database file
2016-07-15 15:07:25,573 - __main__ - DEBUG - there is a error
Traceback (most recent call last):
  File "spyder.py", line 50, in spyder
    cur2.execute('select count(*) from People_Inf where Name_Url=?', (people_list,))
OperationalError: unable to open database file
2016-07-15 15:07:25,644 - __main__ - DEBUG - there is a error
Traceback (most recent call last):
  File "spyder.py", line 50, in spyder
    cur2.execute('select count(*) from People_Inf where Name_Url=?', (people_list,))
OperationalError: unable to open database file
2016-07-15 15:07:25,712 - __main__ - DEBUG - there is a error
Traceback (most recent call last):
  File "spyder.py", line 50, in spyder
    cur2.execute('select count(*) from People_Inf where Name_Url=?', (people_list,))
OperationalError: unable to open database file
2016-07-15 15:07:25,779 - __main__ - DEBUG - there is a error
Traceback (most recent call last):
  File "spyder.py", line 50, in spyder
    cur2.execute('select count(*) from People_Inf where Name_Url=?', (people_list,))
OperationalError: unable to open database file
2016-07-15 15:07:25,850 - __main__ - DEBUG - there is a error
Traceback (most recent call last):
  File "spyder.py", line 50, in spyder
    cur2.execute('select count(*) from People_Inf where Name_Url=?', (people_list,))
OperationalError: unable to open database file
2016-07-15 15:07:25,918 - __main__ - DEBUG - there is a error
Traceback (most recent call last):
  File "spyder.py", line 50, in spyder
    cur2.execute('select count(*) from People_Inf where Name_Url=?', (people_list,))
OperationalError: unable to open database file
2016-07-15 15:07:25,992 - __main__ - DEBUG - there is a error
Traceback (most recent call last):
  File "spyder.py", line 50, in spyder
    cur2.execute('select count(*) from People_Inf where Name_Url=?', (people_list,))
OperationalError: unable to open database file
2016-07-15 15:07:26,059 - __main__ - DEBUG - there is a error
Traceback (most recent call last):
  File "spyder.py", line 50, in spyder
    cur2.execute('select count(*) from People_Inf where Name_Url=?', (people_list,))
OperationalError: unable to open database file
2016-07-15 15:07:26,125 - __main__ - DEBUG - there is a error
Traceback (most recent call last):
  File "spyder.py", line 50, in spyder
    cur2.execute('select count(*) from People_Inf where Name_Url=?', (people_list,))
OperationalError: unable to open database file
2016-07-15 15:07:26,193 - __main__ - DEBUG - there is a error
Traceback (most recent call last):
  File "spyder.py", line 50, in spyder
    cur2.execute('select count(*) from People_Inf where Name_Url=?', (people_list,))
OperationalError: unable to open database file
2016-07-15 15:07:26,261 - __main__ - DEBUG - there is a error
Traceback (most recent call last):
  File "spyder.py", line 50, in spyder
    cur2.execute('select count(*) from People_Inf where Name_Url=?', (people_list,))
OperationalError: unable to open database file
2016-07-15 15:07:26,329 - __main__ - DEBUG - there is a error
Traceback (most recent call last):
  File "spyder.py", line 50, in spyder
    cur2.execute('select count(*) from People_Inf where Name_Url=?', (people_list,))
OperationalError: unable to open database file
2016-07-15 15:07:26,397 - __main__ - DEBUG - there is a error
Traceback (most recent call last):
  File "spyder.py", line 50, in spyder
    cur2.execute('select count(*) from People_Inf where Name_Url=?', (people_list,))
OperationalError: unable to open database file
2016-07-15 15:07:26,465 - __main__ - DEBUG - there is a error
Traceback (most recent call last):
  File "spyder.py", line 50, in spyder
    cur2.execute('select count(*) from People_Inf where Name_Url=?', (people_list,))
OperationalError: unable to open database file
2016-07-15 15:07:26,533 - __main__ - DEBUG - there is a error
Traceback (most recent call last):
  File "spyder.py", line 50, in spyder
    cur2.execute('select count(*) from People_Inf where Name_Url=?', (people_list,))
OperationalError: unable to open database file
2016-07-15 15:07:26,602 - __main__ - DEBUG - there is a error
Traceback (most recent call last):
  File "spyder.py", line 50, in spyder
    cur2.execute('select count(*) from People_Inf where Name_Url=?', (people_list,))
OperationalError: unable to open database file
2016-07-15 15:07:26,698 - __main__ - DEBUG - there is a error
Traceback (most recent call last):
  File "spyder.py", line 50, in spyder
    cur2.execute('select count(*) from People_Inf where Name_Url=?', (people_list,))
OperationalError: unable to open database file
2016-07-15 15:07:26,768 - __main__ - DEBUG - there is a error
Traceback (most recent call last):
  File "spyder.py", line 50, in spyder
    cur2.execute('select count(*) from People_Inf where Name_Url=?', (people_list,))
OperationalError: unable to open database file
2016-07-15 15:07:26,846 - __main__ - DEBUG - there is a error
Traceback (most recent call last):
  File "spyder.py", line 50, in spyder
    cur2.execute('select count(*) from People_Inf where Name_Url=?', (people_list,))
OperationalError: unable to open database file
2016-07-15 15:07:26,926 - __main__ - DEBUG - there is a error
Traceback (most recent call last):
  File "spyder.py", line 50, in spyder
    cur2.execute('select count(*) from People_Inf where Name_Url=?', (people_list,))
OperationalError: unable to open database file
2016-07-15 15:07:27,008 - __main__ - DEBUG - there is a error
Traceback (most recent call last):
  File "spyder.py", line 50, in spyder
    cur2.execute('select count(*) from People_Inf where Name_Url=?', (people_list,))
OperationalError: unable to open database file
2016-07-15 15:07:27,085 - __main__ - DEBUG - there is a error
Traceback (most recent call last):
  File "spyder.py", line 50, in spyder
    cur2.execute('select count(*) from People_Inf where Name_Url=?', (people_list,))
OperationalError: unable to open database file
2016-07-15 15:07:27,164 - __main__ - DEBUG - there is a error
Traceback (most recent call last):
  File "spyder.py", line 50, in spyder
    cur2.execute('select count(*) from People_Inf where Name_Url=?', (people_list,))
OperationalError: unable to open database file
2016-07-15 15:07:27,238 - __main__ - DEBUG - there is a error
Traceback (most recent call last):
  File "spyder.py", line 50, in spyder
    cur2.execute('select count(*) from People_Inf where Name_Url=?', (people_list,))
OperationalError: unable to open database file
2016-07-15 15:07:27,314 - __main__ - DEBUG - there is a error
Traceback (most recent call last):
  File "spyder.py", line 50, in spyder
    cur2.execute('select count(*) from People_Inf where Name_Url=?', (people_list,))
OperationalError: unable to open database file
2016-07-15 15:07:27,394 - __main__ - DEBUG - there is a error
Traceback (most recent call last):
  File "spyder.py", line 50, in spyder
    cur2.execute('select count(*) from People_Inf where Name_Url=?', (people_list,))
OperationalError: unable to open database file
2016-07-15 15:07:27,504 - __main__ - DEBUG - there is a error
Traceback (most recent call last):
  File "spyder.py", line 50, in spyder
    cur2.execute('select count(*) from People_Inf where Name_Url=?', (people_list,))
OperationalError: unable to open database file
2016-07-15 15:07:27,610 - __main__ - DEBUG - there is a error
Traceback (most recent call last):
  File "spyder.py", line 50, in spyder
    cur2.execute('select count(*) from People_Inf where Name_Url=?', (people_list,))
OperationalError: unable to open database file
2016-07-15 15:07:27,702 - __main__ - DEBUG - there is a error
Traceback (most recent call last):
  File "spyder.py", line 50, in spyder
    cur2.execute('select count(*) from People_Inf where Name_Url=?', (people_list,))
OperationalError: unable to open database file
2016-07-15 15:07:27,794 - __main__ - DEBUG - there is a error
Traceback (most recent call last):
  File "spyder.py", line 50, in spyder
    cur2.execute('select count(*) from People_Inf where Name_Url=?', (people_list,))
OperationalError: unable to open database file
2016-07-15 15:07:27,910 - __main__ - DEBUG - there is a error
Traceback (most recent call last):
  File "spyder.py", line 50, in spyder
    cur2.execute('select count(*) from People_Inf where Name_Url=?', (people_list,))
OperationalError: unable to open database file
2016-07-15 15:07:28,021 - __main__ - DEBUG - there is a error
Traceback (most recent call last):
  File "spyder.py", line 50, in spyder
    cur2.execute('select count(*) from People_Inf where Name_Url=?', (people_list,))
OperationalError: unable to open database file
2016-07-15 15:07:28,121 - __main__ - DEBUG - there is a error
Traceback (most recent call last):
  File "spyder.py", line 50, in spyder
    cur2.execute('select count(*) from People_Inf where Name_Url=?', (people_list,))
OperationalError: unable to open database file
2016-07-15 15:07:28,544 - __main__ - DEBUG - there is a error
Traceback (most recent call last):
  File "spyder.py", line 50, in spyder
    cur2.execute('select count(*) from People_Inf where Name_Url=?', (people_list,))
OperationalError: unable to open database file
2016-07-15 15:07:28,626 - __main__ - DEBUG - there is a error
Traceback (most recent call last):
  File "spyder.py", line 50, in spyder
    cur2.execute('select count(*) from People_Inf where Name_Url=?', (people_list,))
OperationalError: unable to open database file
2016-07-15 15:07:28,778 - __main__ - DEBUG - there is a error
Traceback (most recent call last):
  File "spyder.py", line 50, in spyder
    cur2.execute('select count(*) from People_Inf where Name_Url=?', (people_list,))
OperationalError: unable to open database file
2016-07-15 15:07:30,052 - __main__ - DEBUG - there is a error
Traceback (most recent call last):
  File "spyder.py", line 50, in spyder
    cur2.execute('select count(*) from People_Inf where Name_Url=?', (people_list,))
OperationalError: unable to open database file
2016-07-15 15:07:30,305 - __main__ - DEBUG - there is a error
Traceback (most recent call last):
  File "spyder.py", line 50, in spyder
    cur2.execute('select count(*) from People_Inf where Name_Url=?', (people_list,))
OperationalError: unable to open database file
2016-07-15 15:07:30,404 - __main__ - DEBUG - there is a error
Traceback (most recent call last):
  File "spyder.py", line 50, in spyder
    cur2.execute('select count(*) from People_Inf where Name_Url=?', (people_list,))
OperationalError: unable to open database file
2016-07-15 15:07:30,472 - __main__ - DEBUG - there is a error
Traceback (most recent call last):
  File "spyder.py", line 50, in spyder
    cur2.execute('select count(*) from People_Inf where Name_Url=?', (people_list,))
OperationalError: unable to open database file
2016-07-15 15:07:30,571 - __main__ - DEBUG - there is a error
Traceback (most recent call last):
  File "spyder.py", line 50, in spyder
    cur2.execute('select count(*) from People_Inf where Name_Url=?', (people_list,))
OperationalError: unable to open database file
2016-07-15 15:07:30,640 - __main__ - DEBUG - there is a error
Traceback (most recent call last):
  File "spyder.py", line 50, in spyder
    cur2.execute('select count(*) from People_Inf where Name_Url=?', (people_list,))
OperationalError: unable to open database file
2016-07-15 15:07:30,710 - __main__ - DEBUG - there is a error
Traceback (most recent call last):
  File "spyder.py", line 50, in spyder
    cur2.execute('select count(*) from People_Inf where Name_Url=?', (people_list,))
OperationalError: unable to open database file
2016-07-15 15:07:30,779 - __main__ - DEBUG - there is a error
Traceback (most recent call last):
  File "spyder.py", line 50, in spyder
    cur2.execute('select count(*) from People_Inf where Name_Url=?', (people_list,))
OperationalError: unable to open database file
2016-07-15 15:07:30,853 - __main__ - DEBUG - there is a error
Traceback (most recent call last):
  File "spyder.py", line 50, in spyder
    cur2.execute('select count(*) from People_Inf where Name_Url=?', (people_list,))
OperationalError: unable to open database file
2016-07-15 15:07:30,927 - __main__ - DEBUG - there is a error
Traceback (most recent call last):
  File "spyder.py", line 50, in spyder
    cur2.execute('select count(*) from People_Inf where Name_Url=?', (people_list,))
OperationalError: unable to open database file
2016-07-15 15:07:31,004 - __main__ - DEBUG - there is a error
Traceback (most recent call last):
  File "spyder.py", line 50, in spyder
    cur2.execute('select count(*) from People_Inf where Name_Url=?', (people_list,))
OperationalError: unable to open database file
2016-07-15 15:07:31,078 - __main__ - DEBUG - there is a error
Traceback (most recent call last):
  File "spyder.py", line 50, in spyder
    cur2.execute('select count(*) from People_Inf where Name_Url=?', (people_list,))
OperationalError: unable to open database file
2016-07-15 15:07:31,152 - __main__ - DEBUG - there is a error
Traceback (most recent call last):
  File "spyder.py", line 50, in spyder
    cur2.execute('select count(*) from People_Inf where Name_Url=?', (people_list,))
OperationalError: unable to open database file
2016-07-15 15:07:31,222 - __main__ - DEBUG - there is a error
Traceback (most recent call last):
  File "spyder.py", line 50, in spyder
    cur2.execute('select count(*) from People_Inf where Name_Url=?', (people_list,))
OperationalError: unable to open database file
2016-07-15 15:07:31,295 - __main__ - DEBUG - there is a error
Traceback (most recent call last):
  File "spyder.py", line 50, in spyder
    cur2.execute('select count(*) from People_Inf where Name_Url=?', (people_list,))
OperationalError: unable to open database file
2016-07-15 15:07:31,390 - __main__ - DEBUG - there is a error
Traceback (most recent call last):
  File "spyder.py", line 50, in spyder
    cur2.execute('select count(*) from People_Inf where Name_Url=?', (people_list,))
OperationalError: unable to open database file
2016-07-15 15:07:31,464 - __main__ - DEBUG - there is a error
Traceback (most recent call last):
  File "spyder.py", line 50, in spyder
    cur2.execute('select count(*) from People_Inf where Name_Url=?', (people_list,))
OperationalError: unable to open database file
2016-07-15 15:07:31,536 - __main__ - DEBUG - there is a error
Traceback (most recent call last):
  File "spyder.py", line 50, in spyder
    cur2.execute('select count(*) from People_Inf where Name_Url=?', (people_list,))
OperationalError: unable to open database file
2016-07-15 15:07:31,608 - __main__ - DEBUG - there is a error
Traceback (most recent call last):
  File "spyder.py", line 50, in spyder
    cur2.execute('select count(*) from People_Inf where Name_Url=?', (people_list,))
OperationalError: unable to open database file
2016-07-15 15:07:31,682 - __main__ - DEBUG - there is a error
Traceback (most recent call last):
  File "spyder.py", line 50, in spyder
    cur2.execute('select count(*) from People_Inf where Name_Url=?', (people_list,))
OperationalError: unable to open database file
2016-07-15 15:07:31,756 - __main__ - DEBUG - there is a error
Traceback (most recent call last):
  File "spyder.py", line 50, in spyder
    cur2.execute('select count(*) from People_Inf where Name_Url=?', (people_list,))
OperationalError: unable to open database file
2016-07-15 15:07:31,852 - __main__ - DEBUG - there is a error
Traceback (most recent call last):
  File "spyder.py", line 50, in spyder
    cur2.execute('select count(*) from People_Inf where Name_Url=?', (people_list,))
OperationalError: unable to open database file
2016-07-15 15:07:31,928 - __main__ - DEBUG - there is a error
Traceback (most recent call last):
  File "spyder.py", line 50, in spyder
    cur2.execute('select count(*) from People_Inf where Name_Url=?', (people_list,))
OperationalError: unable to open database file
2016-07-15 15:07:32,002 - __main__ - DEBUG - there is a error
Traceback (most recent call last):
  File "spyder.py", line 50, in spyder
    cur2.execute('select count(*) from People_Inf where Name_Url=?', (people_list,))
OperationalError: unable to open database file
2016-07-15 15:07:32,073 - __main__ - DEBUG - there is a error
Traceback (most recent call last):
  File "spyder.py", line 50, in spyder
    cur2.execute('select count(*) from People_Inf where Name_Url=?', (people_list,))
OperationalError: unable to open database file
2016-07-15 15:07:32,148 - __main__ - DEBUG - there is a error
Traceback (most recent call last):
  File "spyder.py", line 50, in spyder
    cur2.execute('select count(*) from People_Inf where Name_Url=?', (people_list,))
OperationalError: unable to open database file
2016-07-15 15:07:32,226 - __main__ - DEBUG - there is a error
Traceback (most recent call last):
  File "spyder.py", line 50, in spyder
    cur2.execute('select count(*) from People_Inf where Name_Url=?', (people_list,))
OperationalError: unable to open database file
2016-07-15 15:07:32,305 - __main__ - DEBUG - there is a error
Traceback (most recent call last):
  File "spyder.py", line 50, in spyder
    cur2.execute('select count(*) from People_Inf where Name_Url=?', (people_list,))
OperationalError: unable to open database file
2016-07-15 15:07:32,456 - __main__ - DEBUG - there is a error
Traceback (most recent call last):
  File "spyder.py", line 50, in spyder
    cur2.execute('select count(*) from People_Inf where Name_Url=?', (people_list,))
OperationalError: unable to open database file
2016-07-15 15:07:32,540 - __main__ - DEBUG - there is a error
Traceback (most recent call last):
  File "spyder.py", line 50, in spyder
    cur2.execute('select count(*) from People_Inf where Name_Url=?', (people_list,))
OperationalError: unable to open database file
2016-07-15 15:07:32,639 - __main__ - DEBUG - there is a error
Traceback (most recent call last):
  File "spyder.py", line 50, in spyder
    cur2.execute('select count(*) from People_Inf where Name_Url=?', (people_list,))
OperationalError: unable to open database file
2016-07-15 15:07:32,727 - __main__ - DEBUG - there is a error
Traceback (most recent call last):
  File "spyder.py", line 50, in spyder
    cur2.execute('select count(*) from People_Inf where Name_Url=?', (people_list,))
OperationalError: unable to open database file
2016-07-15 15:07:32,815 - __main__ - DEBUG - there is a error
Traceback (most recent call last):
  File "spyder.py", line 50, in spyder
    cur2.execute('select count(*) from People_Inf where Name_Url=?', (people_list,))
OperationalError: unable to open database file
2016-07-15 15:07:32,882 - __main__ - DEBUG - there is a error
Traceback (most recent call last):
  File "spyder.py", line 50, in spyder
    cur2.execute('select count(*) from People_Inf where Name_Url=?', (people_list,))
OperationalError: unable to open database file
2016-07-15 15:07:32,969 - __main__ - DEBUG - there is a error
Traceback (most recent call last):
  File "spyder.py", line 50, in spyder
    cur2.execute('select count(*) from People_Inf where Name_Url=?', (people_list,))
OperationalError: unable to open database file
2016-07-15 15:07:33,050 - __main__ - DEBUG - there is a error
Traceback (most recent call last):
  File "spyder.py", line 50, in spyder
    cur2.execute('select count(*) from People_Inf where Name_Url=?', (people_list,))
OperationalError: unable to open database file
2016-07-15 15:07:33,129 - __main__ - DEBUG - there is a error
Traceback (most recent call last):
  File "spyder.py", line 50, in spyder
    cur2.execute('select count(*) from People_Inf where Name_Url=?', (people_list,))
OperationalError: unable to open database file
2016-07-15 15:07:33,206 - __main__ - DEBUG - there is a error
Traceback (most recent call last):
  File "spyder.py", line 50, in spyder
    cur2.execute('select count(*) from People_Inf where Name_Url=?', (people_list,))
OperationalError: unable to open database file
2016-07-15 15:07:33,285 - __main__ - DEBUG - there is a error
Traceback (most recent call last):
  File "spyder.py", line 50, in spyder
    cur2.execute('select count(*) from People_Inf where Name_Url=?', (people_list,))
OperationalError: unable to open database file
2016-07-15 15:07:33,406 - __main__ - DEBUG - there is a error
Traceback (most recent call last):
  File "spyder.py", line 50, in spyder
    cur2.execute('select count(*) from People_Inf where Name_Url=?', (people_list,))
OperationalError: unable to open database file
2016-07-15 15:07:33,485 - __main__ - DEBUG - there is a error
Traceback (most recent call last):
  File "spyder.py", line 50, in spyder
    cur2.execute('select count(*) from People_Inf where Name_Url=?', (people_list,))
OperationalError: unable to open database file
2016-07-15 15:07:33,567 - __main__ - DEBUG - there is a error
Traceback (most recent call last):
  File "spyder.py", line 50, in spyder
    cur2.execute('select count(*) from People_Inf where Name_Url=?', (people_list,))
OperationalError: unable to open database file
2016-07-15 15:07:33,649 - __main__ - DEBUG - there is a error
Traceback (most recent call last):
  File "spyder.py", line 50, in spyder
    cur2.execute('select count(*) from People_Inf where Name_Url=?', (people_list,))
OperationalError: unable to open database file
2016-07-15 15:07:33,723 - __main__ - DEBUG - there is a error
Traceback (most recent call last):
  File "spyder.py", line 50, in spyder
    cur2.execute('select count(*) from People_Inf where Name_Url=?', (people_list,))
OperationalError: unable to open database file
2016-07-15 15:07:34,102 - __main__ - DEBUG - there is a error
Traceback (most recent call last):
  File "spyder.py", line 50, in spyder
    cur2.execute('select count(*) from People_Inf where Name_Url=?', (people_list,))
OperationalError: unable to open database file
2016-07-15 15:07:34,216 - __main__ - DEBUG - there is a error
Traceback (most recent call last):
  File "spyder.py", line 50, in spyder
    cur2.execute('select count(*) from People_Inf where Name_Url=?', (people_list,))
OperationalError: unable to open database file
2016-07-15 15:07:34,288 - __main__ - DEBUG - there is a error
Traceback (most recent call last):
  File "spyder.py", line 50, in spyder
    cur2.execute('select count(*) from People_Inf where Name_Url=?', (people_list,))
OperationalError: unable to open database file
2016-07-15 15:07:34,365 - __main__ - DEBUG - there is a error
Traceback (most recent call last):
  File "spyder.py", line 50, in spyder
    cur2.execute('select count(*) from People_Inf where Name_Url=?', (people_list,))
OperationalError: unable to open database file
2016-07-15 15:07:34,437 - __main__ - DEBUG - there is a error
Traceback (most recent call last):
  File "spyder.py", line 50, in spyder
    cur2.execute('select count(*) from People_Inf where Name_Url=?', (people_list,))
OperationalError: unable to open database file
2016-07-15 15:07:34,575 - __main__ - DEBUG - there is a error
Traceback (most recent call last):
  File "spyder.py", line 50, in spyder
    cur2.execute('select count(*) from People_Inf where Name_Url=?', (people_list,))
OperationalError: unable to open database file
2016-07-15 15:07:34,667 - __main__ - DEBUG - there is a error
Traceback (most recent call last):
  File "spyder.py", line 50, in spyder
    cur2.execute('select count(*) from People_Inf where Name_Url=?', (people_list,))
OperationalError: unable to open database file
2016-07-15 15:07:34,744 - __main__ - DEBUG - there is a error
Traceback (most recent call last):
  File "spyder.py", line 50, in spyder
    cur2.execute('select count(*) from People_Inf where Name_Url=?', (people_list,))
OperationalError: unable to open database file
2016-07-15 15:07:34,820 - __main__ - DEBUG - there is a error
Traceback (most recent call last):
  File "spyder.py", line 50, in spyder
    cur2.execute('select count(*) from People_Inf where Name_Url=?', (people_list,))
OperationalError: unable to open database file
2016-07-15 15:07:35,117 - __main__ - DEBUG - there is a error
Traceback (most recent call last):
  File "spyder.py", line 50, in spyder
    cur2.execute('select count(*) from People_Inf where Name_Url=?', (people_list,))
OperationalError: unable to open database file
2016-07-15 15:07:35,199 - __main__ - DEBUG - there is a error
Traceback (most recent call last):
  File "spyder.py", line 50, in spyder
    cur2.execute('select count(*) from People_Inf where Name_Url=?', (people_list,))
OperationalError: unable to open database file
2016-07-15 15:07:35,281 - __main__ - DEBUG - there is a error
Traceback (most recent call last):
  File "spyder.py", line 50, in spyder
    cur2.execute('select count(*) from People_Inf where Name_Url=?', (people_list,))
OperationalError: unable to open database file
2016-07-15 15:07:35,359 - __main__ - DEBUG - there is a error
Traceback (most recent call last):
  File "spyder.py", line 50, in spyder
    cur2.execute('select count(*) from People_Inf where Name_Url=?', (people_list,))
OperationalError: unable to open database file
2016-07-15 15:07:35,441 - __main__ - DEBUG - there is a error
Traceback (most recent call last):
  File "spyder.py", line 50, in spyder
    cur2.execute('select count(*) from People_Inf where Name_Url=?', (people_list,))
OperationalError: unable to open database file
2016-07-15 15:07:35,525 - __main__ - DEBUG - there is a error
Traceback (most recent call last):
  File "spyder.py", line 50, in spyder
    cur2.execute('select count(*) from People_Inf where Name_Url=?', (people_list,))
OperationalError: unable to open database file
2016-07-15 15:07:35,596 - __main__ - DEBUG - there is a error
Traceback (most recent call last):
  File "spyder.py", line 50, in spyder
    cur2.execute('select count(*) from People_Inf where Name_Url=?', (people_list,))
OperationalError: unable to open database file
2016-07-15 15:07:35,678 - __main__ - DEBUG - there is a error
Traceback (most recent call last):
  File "spyder.py", line 50, in spyder
    cur2.execute('select count(*) from People_Inf where Name_Url=?', (people_list,))
OperationalError: unable to open database file
2016-07-15 15:07:35,759 - __main__ - DEBUG - there is a error
Traceback (most recent call last):
  File "spyder.py", line 50, in spyder
    cur2.execute('select count(*) from People_Inf where Name_Url=?', (people_list,))
OperationalError: unable to open database file
2016-07-15 15:07:35,839 - __main__ - DEBUG - there is a error
Traceback (most recent call last):
  File "spyder.py", line 50, in spyder
    cur2.execute('select count(*) from People_Inf where Name_Url=?', (people_list,))
OperationalError: unable to open database file
2016-07-15 15:07:35,909 - __main__ - DEBUG - there is a error
Traceback (most recent call last):
  File "spyder.py", line 50, in spyder
    cur2.execute('select count(*) from People_Inf where Name_Url=?', (people_list,))
OperationalError: unable to open database file
2016-07-15 15:07:35,983 - __main__ - DEBUG - there is a error
Traceback (most recent call last):
  File "spyder.py", line 50, in spyder
    cur2.execute('select count(*) from People_Inf where Name_Url=?', (people_list,))
OperationalError: unable to open database file
2016-07-15 15:07:36,063 - __main__ - DEBUG - there is a error
Traceback (most recent call last):
  File "spyder.py", line 50, in spyder
    cur2.execute('select count(*) from People_Inf where Name_Url=?', (people_list,))
OperationalError: unable to open database file
2016-07-15 15:07:36,148 - __main__ - DEBUG - there is a error
Traceback (most recent call last):
  File "spyder.py", line 50, in spyder
    cur2.execute('select count(*) from People_Inf where Name_Url=?', (people_list,))
OperationalError: unable to open database file
2016-07-15 15:07:36,221 - __main__ - DEBUG - there is a error
Traceback (most recent call last):
  File "spyder.py", line 50, in spyder
    cur2.execute('select count(*) from People_Inf where Name_Url=?', (people_list,))
OperationalError: unable to open database file
2016-07-15 15:07:36,329 - __main__ - DEBUG - there is a error
Traceback (most recent call last):
  File "spyder.py", line 50, in spyder
    cur2.execute('select count(*) from People_Inf where Name_Url=?', (people_list,))
OperationalError: unable to open database file
2016-07-15 15:07:36,407 - __main__ - DEBUG - there is a error
Traceback (most recent call last):
  File "spyder.py", line 50, in spyder
    cur2.execute('select count(*) from People_Inf where Name_Url=?', (people_list,))
OperationalError: unable to open database file
2016-07-15 15:07:36,479 - __main__ - DEBUG - there is a error
Traceback (most recent call last):
  File "spyder.py", line 50, in spyder
    cur2.execute('select count(*) from People_Inf where Name_Url=?', (people_list,))
OperationalError: unable to open database file
2016-07-15 15:07:36,552 - __main__ - DEBUG - there is a error
Traceback (most recent call last):
  File "spyder.py", line 50, in spyder
    cur2.execute('select count(*) from People_Inf where Name_Url=?', (people_list,))
OperationalError: unable to open database file
2016-07-15 15:07:36,640 - __main__ - DEBUG - there is a error
Traceback (most recent call last):
  File "spyder.py", line 50, in spyder
    cur2.execute('select count(*) from People_Inf where Name_Url=?', (people_list,))
OperationalError: unable to open database file
2016-07-15 15:07:36,719 - __main__ - DEBUG - there is a error
Traceback (most recent call last):
  File "spyder.py", line 50, in spyder
    cur2.execute('select count(*) from People_Inf where Name_Url=?', (people_list,))
OperationalError: unable to open database file
2016-07-15 15:07:36,788 - __main__ - DEBUG - there is a error
Traceback (most recent call last):
  File "spyder.py", line 50, in spyder
    cur2.execute('select count(*) from People_Inf where Name_Url=?', (people_list,))
OperationalError: unable to open database file
2016-07-15 15:07:36,867 - __main__ - DEBUG - there is a error
Traceback (most recent call last):
  File "spyder.py", line 50, in spyder
    cur2.execute('select count(*) from People_Inf where Name_Url=?', (people_list,))
OperationalError: unable to open database file
2016-07-15 15:07:36,990 - __main__ - DEBUG - there is a error
Traceback (most recent call last):
  File "spyder.py", line 50, in spyder
    cur2.execute('select count(*) from People_Inf where Name_Url=?', (people_list,))
OperationalError: unable to open database file
2016-07-15 15:07:37,087 - __main__ - DEBUG - there is a error
Traceback (most recent call last):
  File "spyder.py", line 50, in spyder
    cur2.execute('select count(*) from People_Inf where Name_Url=?', (people_list,))
OperationalError: unable to open database file
2016-07-15 15:07:37,154 - __main__ - DEBUG - there is a error
Traceback (most recent call last):
  File "spyder.py", line 50, in spyder
    cur2.execute('select count(*) from People_Inf where Name_Url=?', (people_list,))
OperationalError: unable to open database file
2016-07-15 15:07:37,253 - __main__ - DEBUG - there is a error
Traceback (most recent call last):
  File "spyder.py", line 50, in spyder
    cur2.execute('select count(*) from People_Inf where Name_Url=?', (people_list,))
OperationalError: unable to open database file
2016-07-15 15:07:37,318 - __main__ - DEBUG - there is a error
Traceback (most recent call last):
  File "spyder.py", line 50, in spyder
    cur2.execute('select count(*) from People_Inf where Name_Url=?', (people_list,))
OperationalError: unable to open database file
2016-07-15 15:07:37,395 - __main__ - DEBUG - there is a error
Traceback (most recent call last):
  File "spyder.py", line 50, in spyder
    cur2.execute('select count(*) from People_Inf where Name_Url=?', (people_list,))
OperationalError: unable to open database file
2016-07-15 15:07:37,463 - __main__ - DEBUG - there is a error
Traceback (most recent call last):
  File "spyder.py", line 50, in spyder
    cur2.execute('select count(*) from People_Inf where Name_Url=?', (people_list,))
OperationalError: unable to open database file
2016-07-15 15:07:37,531 - __main__ - DEBUG - there is a error
Traceback (most recent call last):
  File "spyder.py", line 50, in spyder
    cur2.execute('select count(*) from People_Inf where Name_Url=?', (people_list,))
OperationalError: unable to open database file
2016-07-15 15:07:37,594 - __main__ - DEBUG - there is a error
Traceback (most recent call last):
  File "spyder.py", line 50, in spyder
    cur2.execute('select count(*) from People_Inf where Name_Url=?', (people_list,))
OperationalError: unable to open database file
2016-07-15 15:07:37,661 - __main__ - DEBUG - there is a error
Traceback (most recent call last):
  File "spyder.py", line 50, in spyder
    cur2.execute('select count(*) from People_Inf where Name_Url=?', (people_list,))
OperationalError: unable to open database file
2016-07-15 15:07:37,725 - __main__ - DEBUG - there is a error
Traceback (most recent call last):
  File "spyder.py", line 50, in spyder
    cur2.execute('select count(*) from People_Inf where Name_Url=?', (people_list,))
OperationalError: unable to open database file
2016-07-15 15:07:37,791 - __main__ - DEBUG - there is a error
Traceback (most recent call last):
  File "spyder.py", line 50, in spyder
    cur2.execute('select count(*) from People_Inf where Name_Url=?', (people_list,))
OperationalError: unable to open database file
2016-07-15 15:07:37,855 - __main__ - DEBUG - there is a error
Traceback (most recent call last):
  File "spyder.py", line 50, in spyder
    cur2.execute('select count(*) from People_Inf where Name_Url=?', (people_list,))
OperationalError: unable to open database file
2016-07-15 15:07:37,918 - __main__ - DEBUG - there is a error
Traceback (most recent call last):
  File "spyder.py", line 50, in spyder
    cur2.execute('select count(*) from People_Inf where Name_Url=?', (people_list,))
OperationalError: unable to open database file
2016-07-15 15:07:37,986 - __main__ - DEBUG - there is a error
Traceback (most recent call last):
  File "spyder.py", line 50, in spyder
    cur2.execute('select count(*) from People_Inf where Name_Url=?', (people_list,))
OperationalError: unable to open database file
2016-07-15 15:07:38,055 - __main__ - DEBUG - there is a error
Traceback (most recent call last):
  File "spyder.py", line 50, in spyder
    cur2.execute('select count(*) from People_Inf where Name_Url=?', (people_list,))
OperationalError: unable to open database file
2016-07-15 15:07:38,122 - __main__ - DEBUG - there is a error
Traceback (most recent call last):
  File "spyder.py", line 50, in spyder
    cur2.execute('select count(*) from People_Inf where Name_Url=?', (people_list,))
OperationalError: unable to open database file
2016-07-15 15:07:38,210 - __main__ - DEBUG - there is a error
Traceback (most recent call last):
  File "spyder.py", line 50, in spyder
    cur2.execute('select count(*) from People_Inf where Name_Url=?', (people_list,))
OperationalError: unable to open database file
2016-07-15 15:07:38,273 - __main__ - DEBUG - there is a error
Traceback (most recent call last):
  File "spyder.py", line 50, in spyder
    cur2.execute('select count(*) from People_Inf where Name_Url=?', (people_list,))
OperationalError: unable to open database file
2016-07-15 15:07:38,338 - __main__ - DEBUG - there is a error
Traceback (most recent call last):
  File "spyder.py", line 50, in spyder
    cur2.execute('select count(*) from People_Inf where Name_Url=?', (people_list,))
OperationalError: unable to open database file
2016-07-15 15:07:38,401 - __main__ - DEBUG - there is a error
Traceback (most recent call last):
  File "spyder.py", line 50, in spyder
    cur2.execute('select count(*) from People_Inf where Name_Url=?', (people_list,))
OperationalError: unable to open database file
2016-07-15 15:07:38,463 - __main__ - DEBUG - there is a error
Traceback (most recent call last):
  File "spyder.py", line 50, in spyder
    cur2.execute('select count(*) from People_Inf where Name_Url=?', (people_list,))
OperationalError: unable to open database file
2016-07-15 15:07:38,527 - __main__ - DEBUG - there is a error
Traceback (most recent call last):
  File "spyder.py", line 50, in spyder
    cur2.execute('select count(*) from People_Inf where Name_Url=?', (people_list,))
OperationalError: unable to open database file
2016-07-15 15:07:38,591 - __main__ - DEBUG - there is a error
Traceback (most recent call last):
  File "spyder.py", line 50, in spyder
    cur2.execute('select count(*) from People_Inf where Name_Url=?', (people_list,))
OperationalError: unable to open database file
2016-07-15 15:07:38,654 - __main__ - DEBUG - there is a error
Traceback (most recent call last):
  File "spyder.py", line 50, in spyder
    cur2.execute('select count(*) from People_Inf where Name_Url=?', (people_list,))
OperationalError: unable to open database file
2016-07-15 15:07:38,716 - __main__ - DEBUG - there is a error
Traceback (most recent call last):
  File "spyder.py", line 50, in spyder
    cur2.execute('select count(*) from People_Inf where Name_Url=?', (people_list,))
OperationalError: unable to open database file
2016-07-15 15:07:38,782 - __main__ - DEBUG - there is a error
Traceback (most recent call last):
  File "spyder.py", line 50, in spyder
    cur2.execute('select count(*) from People_Inf where Name_Url=?', (people_list,))
OperationalError: unable to open database file
2016-07-15 15:07:38,845 - __main__ - DEBUG - there is a error
Traceback (most recent call last):
  File "spyder.py", line 50, in spyder
    cur2.execute('select count(*) from People_Inf where Name_Url=?', (people_list,))
OperationalError: unable to open database file
2016-07-15 15:07:38,907 - __main__ - DEBUG - there is a error
Traceback (most recent call last):
  File "spyder.py", line 50, in spyder
    cur2.execute('select count(*) from People_Inf where Name_Url=?', (people_list,))
OperationalError: unable to open database file
2016-07-15 15:07:38,989 - __main__ - DEBUG - there is a error
Traceback (most recent call last):
  File "spyder.py", line 50, in spyder
    cur2.execute('select count(*) from People_Inf where Name_Url=?', (people_list,))
OperationalError: unable to open database file
2016-07-15 15:07:39,057 - __main__ - DEBUG - there is a error
Traceback (most recent call last):
  File "spyder.py", line 50, in spyder
    cur2.execute('select count(*) from People_Inf where Name_Url=?', (people_list,))
OperationalError: unable to open database file
2016-07-15 15:07:39,120 - __main__ - DEBUG - there is a error
Traceback (most recent call last):
  File "spyder.py", line 50, in spyder
    cur2.execute('select count(*) from People_Inf where Name_Url=?', (people_list,))
OperationalError: unable to open database file
2016-07-15 15:07:39,185 - __main__ - DEBUG - there is a error
Traceback (most recent call last):
  File "spyder.py", line 50, in spyder
    cur2.execute('select count(*) from People_Inf where Name_Url=?', (people_list,))
OperationalError: unable to open database file
2016-07-15 15:07:39,250 - __main__ - DEBUG - there is a error
Traceback (most recent call last):
  File "spyder.py", line 50, in spyder
    cur2.execute('select count(*) from People_Inf where Name_Url=?', (people_list,))
OperationalError: unable to open database file
2016-07-15 15:07:39,318 - __main__ - DEBUG - there is a error
Traceback (most recent call last):
  File "spyder.py", line 50, in spyder
    cur2.execute('select count(*) from People_Inf where Name_Url=?', (people_list,))
OperationalError: unable to open database file
2016-07-15 15:07:39,382 - __main__ - DEBUG - there is a error
Traceback (most recent call last):
  File "spyder.py", line 50, in spyder
    cur2.execute('select count(*) from People_Inf where Name_Url=?', (people_list,))
OperationalError: unable to open database file
2016-07-15 15:07:39,446 - __main__ - DEBUG - there is a error
Traceback (most recent call last):
  File "spyder.py", line 50, in spyder
    cur2.execute('select count(*) from People_Inf where Name_Url=?', (people_list,))
OperationalError: unable to open database file
2016-07-15 15:07:39,513 - __main__ - DEBUG - there is a error
Traceback (most recent call last):
  File "spyder.py", line 50, in spyder
    cur2.execute('select count(*) from People_Inf where Name_Url=?', (people_list,))
OperationalError: unable to open database file
2016-07-15 15:07:39,590 - __main__ - DEBUG - there is a error
Traceback (most recent call last):
  File "spyder.py", line 50, in spyder
    cur2.execute('select count(*) from People_Inf where Name_Url=?', (people_list,))
OperationalError: unable to open database file
2016-07-15 15:07:39,657 - __main__ - DEBUG - there is a error
Traceback (most recent call last):
  File "spyder.py", line 50, in spyder
    cur2.execute('select count(*) from People_Inf where Name_Url=?', (people_list,))
OperationalError: unable to open database file
2016-07-15 15:07:39,722 - __main__ - DEBUG - there is a error
Traceback (most recent call last):
  File "spyder.py", line 50, in spyder
    cur2.execute('select count(*) from People_Inf where Name_Url=?', (people_list,))
OperationalError: unable to open database file
2016-07-15 15:07:39,803 - __main__ - DEBUG - there is a error
Traceback (most recent call last):
  File "spyder.py", line 50, in spyder
    cur2.execute('select count(*) from People_Inf where Name_Url=?', (people_list,))
OperationalError: unable to open database file
2016-07-15 15:07:39,880 - __main__ - DEBUG - there is a error
Traceback (most recent call last):
  File "spyder.py", line 50, in spyder
    cur2.execute('select count(*) from People_Inf where Name_Url=?', (people_list,))
OperationalError: unable to open database file
2016-07-15 15:07:39,944 - __main__ - DEBUG - there is a error
Traceback (most recent call last):
  File "spyder.py", line 50, in spyder
    cur2.execute('select count(*) from People_Inf where Name_Url=?', (people_list,))
OperationalError: unable to open database file
2016-07-15 15:07:40,019 - __main__ - DEBUG - there is a error
Traceback (most recent call last):
  File "spyder.py", line 50, in spyder
    cur2.execute('select count(*) from People_Inf where Name_Url=?', (people_list,))
OperationalError: unable to open database file
2016-07-15 15:07:40,086 - __main__ - DEBUG - there is a error
Traceback (most recent call last):
  File "spyder.py", line 50, in spyder
    cur2.execute('select count(*) from People_Inf where Name_Url=?', (people_list,))
OperationalError: unable to open database file
2016-07-15 15:07:40,159 - __main__ - DEBUG - there is a error
Traceback (most recent call last):
  File "spyder.py", line 50, in spyder
    cur2.execute('select count(*) from People_Inf where Name_Url=?', (people_list,))
OperationalError: unable to open database file
2016-07-15 15:07:40,224 - __main__ - DEBUG - there is a error
Traceback (most recent call last):
  File "spyder.py", line 50, in spyder
    cur2.execute('select count(*) from People_Inf where Name_Url=?', (people_list,))
OperationalError: unable to open database file
2016-07-15 15:07:40,288 - __main__ - DEBUG - there is a error
Traceback (most recent call last):
  File "spyder.py", line 50, in spyder
    cur2.execute('select count(*) from People_Inf where Name_Url=?', (people_list,))
OperationalError: unable to open database file
2016-07-15 15:07:40,354 - __main__ - DEBUG - there is a error
Traceback (most recent call last):
  File "spyder.py", line 50, in spyder
    cur2.execute('select count(*) from People_Inf where Name_Url=?', (people_list,))
OperationalError: unable to open database file
2016-07-15 15:07:40,429 - __main__ - DEBUG - there is a error
Traceback (most recent call last):
  File "spyder.py", line 50, in spyder
    cur2.execute('select count(*) from People_Inf where Name_Url=?', (people_list,))
OperationalError: unable to open database file
2016-07-15 15:07:40,509 - __main__ - DEBUG - there is a error
Traceback (most recent call last):
  File "spyder.py", line 50, in spyder
    cur2.execute('select count(*) from People_Inf where Name_Url=?', (people_list,))
OperationalError: unable to open database file
2016-07-15 15:07:40,578 - __main__ - DEBUG - there is a error
Traceback (most recent call last):
  File "spyder.py", line 50, in spyder
    cur2.execute('select count(*) from People_Inf where Name_Url=?', (people_list,))
OperationalError: unable to open database file
2016-07-15 15:07:40,670 - __main__ - DEBUG - there is a error
Traceback (most recent call last):
  File "spyder.py", line 50, in spyder
    cur2.execute('select count(*) from People_Inf where Name_Url=?', (people_list,))
OperationalError: unable to open database file
2016-07-15 15:07:40,749 - __main__ - DEBUG - there is a error
Traceback (most recent call last):
  File "spyder.py", line 50, in spyder
    cur2.execute('select count(*) from People_Inf where Name_Url=?', (people_list,))
OperationalError: unable to open database file
2016-07-15 15:07:40,814 - __main__ - DEBUG - there is a error
Traceback (most recent call last):
  File "spyder.py", line 50, in spyder
    cur2.execute('select count(*) from People_Inf where Name_Url=?', (people_list,))
OperationalError: unable to open database file
2016-07-15 15:07:40,880 - __main__ - DEBUG - there is a error
Traceback (most recent call last):
  File "spyder.py", line 50, in spyder
    cur2.execute('select count(*) from People_Inf where Name_Url=?', (people_list,))
OperationalError: unable to open database file
2016-07-15 15:07:40,949 - __main__ - DEBUG - there is a error
Traceback (most recent call last):
  File "spyder.py", line 50, in spyder
    cur2.execute('select count(*) from People_Inf where Name_Url=?', (people_list,))
OperationalError: unable to open database file
2016-07-15 15:07:41,021 - __main__ - DEBUG - there is a error
Traceback (most recent call last):
  File "spyder.py", line 50, in spyder
    cur2.execute('select count(*) from People_Inf where Name_Url=?', (people_list,))
OperationalError: unable to open database file
2016-07-15 15:07:41,134 - __main__ - DEBUG - there is a error
Traceback (most recent call last):
  File "spyder.py", line 50, in spyder
    cur2.execute('select count(*) from People_Inf where Name_Url=?', (people_list,))
OperationalError: unable to open database file
2016-07-15 15:07:41,209 - __main__ - DEBUG - there is a error
Traceback (most recent call last):
  File "spyder.py", line 50, in spyder
    cur2.execute('select count(*) from People_Inf where Name_Url=?', (people_list,))
OperationalError: unable to open database file
2016-07-15 15:07:41,279 - __main__ - DEBUG - there is a error
Traceback (most recent call last):
  File "spyder.py", line 50, in spyder
    cur2.execute('select count(*) from People_Inf where Name_Url=?', (people_list,))
OperationalError: unable to open database file
2016-07-15 15:07:41,346 - __main__ - DEBUG - there is a error
Traceback (most recent call last):
  File "spyder.py", line 50, in spyder
    cur2.execute('select count(*) from People_Inf where Name_Url=?', (people_list,))
OperationalError: unable to open database file
2016-07-15 15:07:41,412 - __main__ - DEBUG - there is a error
Traceback (most recent call last):
  File "spyder.py", line 50, in spyder
    cur2.execute('select count(*) from People_Inf where Name_Url=?', (people_list,))
OperationalError: unable to open database file
2016-07-15 15:07:41,481 - __main__ - DEBUG - there is a error
Traceback (most recent call last):
  File "spyder.py", line 50, in spyder
    cur2.execute('select count(*) from People_Inf where Name_Url=?', (people_list,))
OperationalError: unable to open database file
2016-07-15 15:07:41,547 - __main__ - DEBUG - there is a error
Traceback (most recent call last):
  File "spyder.py", line 50, in spyder
    cur2.execute('select count(*) from People_Inf where Name_Url=?', (people_list,))
OperationalError: unable to open database file
2016-07-15 15:07:41,617 - __main__ - DEBUG - there is a error
Traceback (most recent call last):
  File "spyder.py", line 50, in spyder
    cur2.execute('select count(*) from People_Inf where Name_Url=?', (people_list,))
OperationalError: unable to open database file
2016-07-15 15:07:41,681 - __main__ - DEBUG - there is a error
Traceback (most recent call last):
  File "spyder.py", line 50, in spyder
    cur2.execute('select count(*) from People_Inf where Name_Url=?', (people_list,))
OperationalError: unable to open database file
2016-07-15 15:07:41,766 - __main__ - DEBUG - there is a error
Traceback (most recent call last):
  File "spyder.py", line 50, in spyder
    cur2.execute('select count(*) from People_Inf where Name_Url=?', (people_list,))
OperationalError: unable to open database file
2016-07-15 15:07:41,829 - __main__ - DEBUG - there is a error
Traceback (most recent call last):
  File "spyder.py", line 50, in spyder
    cur2.execute('select count(*) from People_Inf where Name_Url=?', (people_list,))
OperationalError: unable to open database file
2016-07-15 15:07:41,907 - __main__ - DEBUG - there is a error
Traceback (most recent call last):
  File "spyder.py", line 50, in spyder
    cur2.execute('select count(*) from People_Inf where Name_Url=?', (people_list,))
OperationalError: unable to open database file
2016-07-15 15:07:41,973 - __main__ - DEBUG - there is a error
Traceback (most recent call last):
  File "spyder.py", line 50, in spyder
    cur2.execute('select count(*) from People_Inf where Name_Url=?', (people_list,))
OperationalError: unable to open database file
2016-07-15 15:07:42,040 - __main__ - DEBUG - there is a error
Traceback (most recent call last):
  File "spyder.py", line 50, in spyder
    cur2.execute('select count(*) from People_Inf where Name_Url=?', (people_list,))
OperationalError: unable to open database file
2016-07-15 15:07:42,109 - __main__ - DEBUG - there is a error
Traceback (most recent call last):
  File "spyder.py", line 50, in spyder
    cur2.execute('select count(*) from People_Inf where Name_Url=?', (people_list,))
OperationalError: unable to open database file
2016-07-15 15:07:42,186 - __main__ - DEBUG - there is a error
Traceback (most recent call last):
  File "spyder.py", line 50, in spyder
    cur2.execute('select count(*) from People_Inf where Name_Url=?', (people_list,))
OperationalError: unable to open database file
2016-07-15 15:07:42,257 - __main__ - DEBUG - there is a error
Traceback (most recent call last):
  File "spyder.py", line 50, in spyder
    cur2.execute('select count(*) from People_Inf where Name_Url=?', (people_list,))
OperationalError: unable to open database file
2016-07-15 15:07:42,342 - __main__ - DEBUG - there is a error
Traceback (most recent call last):
  File "spyder.py", line 50, in spyder
    cur2.execute('select count(*) from People_Inf where Name_Url=?', (people_list,))
OperationalError: unable to open database file
2016-07-15 15:07:42,531 - __main__ - DEBUG - there is a error
Traceback (most recent call last):
  File "spyder.py", line 50, in spyder
    cur2.execute('select count(*) from People_Inf where Name_Url=?', (people_list,))
OperationalError: unable to open database file
2016-07-15 15:07:42,622 - __main__ - DEBUG - there is a error
Traceback (most recent call last):
  File "spyder.py", line 50, in spyder
    cur2.execute('select count(*) from People_Inf where Name_Url=?', (people_list,))
OperationalError: unable to open database file
2016-07-15 15:07:42,690 - __main__ - DEBUG - there is a error
Traceback (most recent call last):
  File "spyder.py", line 50, in spyder
    cur2.execute('select count(*) from People_Inf where Name_Url=?', (people_list,))
OperationalError: unable to open database file
2016-07-15 15:07:42,765 - __main__ - DEBUG - there is a error
Traceback (most recent call last):
  File "spyder.py", line 50, in spyder
    cur2.execute('select count(*) from People_Inf where Name_Url=?', (people_list,))
OperationalError: unable to open database file
2016-07-15 15:07:42,834 - __main__ - DEBUG - there is a error
Traceback (most recent call last):
  File "spyder.py", line 50, in spyder
    cur2.execute('select count(*) from People_Inf where Name_Url=?', (people_list,))
OperationalError: unable to open database file
2016-07-15 15:07:42,906 - __main__ - DEBUG - there is a error
Traceback (most recent call last):
  File "spyder.py", line 50, in spyder
    cur2.execute('select count(*) from People_Inf where Name_Url=?', (people_list,))
OperationalError: unable to open database file
2016-07-15 15:07:43,039 - __main__ - DEBUG - there is a error
Traceback (most recent call last):
  File "spyder.py", line 50, in spyder
    cur2.execute('select count(*) from People_Inf where Name_Url=?', (people_list,))
OperationalError: unable to open database file
2016-07-15 15:07:43,177 - __main__ - DEBUG - there is a error
Traceback (most recent call last):
  File "spyder.py", line 50, in spyder
    cur2.execute('select count(*) from People_Inf where Name_Url=?', (people_list,))
OperationalError: unable to open database file
2016-07-15 15:07:43,246 - __main__ - DEBUG - there is a error
Traceback (most recent call last):
  File "spyder.py", line 50, in spyder
    cur2.execute('select count(*) from People_Inf where Name_Url=?', (people_list,))
OperationalError: unable to open database file
2016-07-15 15:07:43,318 - __main__ - DEBUG - there is a error
Traceback (most recent call last):
  File "spyder.py", line 50, in spyder
    cur2.execute('select count(*) from People_Inf where Name_Url=?', (people_list,))
OperationalError: unable to open database file
2016-07-15 15:07:43,392 - __main__ - DEBUG - there is a error
Traceback (most recent call last):
  File "spyder.py", line 50, in spyder
    cur2.execute('select count(*) from People_Inf where Name_Url=?', (people_list,))
OperationalError: unable to open database file
2016-07-15 15:07:43,465 - __main__ - DEBUG - there is a error
Traceback (most recent call last):
  File "spyder.py", line 50, in spyder
    cur2.execute('select count(*) from People_Inf where Name_Url=?', (people_list,))
OperationalError: unable to open database file
2016-07-15 15:07:43,583 - __main__ - DEBUG - there is a error
Traceback (most recent call last):
  File "spyder.py", line 50, in spyder
    cur2.execute('select count(*) from People_Inf where Name_Url=?', (people_list,))
OperationalError: unable to open database file
2016-07-15 15:07:43,658 - __main__ - DEBUG - there is a error
Traceback (most recent call last):
  File "spyder.py", line 50, in spyder
    cur2.execute('select count(*) from People_Inf where Name_Url=?', (people_list,))
OperationalError: unable to open database file
2016-07-15 15:07:43,731 - __main__ - DEBUG - there is a error
Traceback (most recent call last):
  File "spyder.py", line 50, in spyder
    cur2.execute('select count(*) from People_Inf where Name_Url=?', (people_list,))
OperationalError: unable to open database file
2016-07-15 15:07:43,805 - __main__ - DEBUG - there is a error
Traceback (most recent call last):
  File "spyder.py", line 50, in spyder
    cur2.execute('select count(*) from People_Inf where Name_Url=?', (people_list,))
OperationalError: unable to open database file
2016-07-15 15:07:43,871 - __main__ - DEBUG - there is a error
Traceback (most recent call last):
  File "spyder.py", line 50, in spyder
    cur2.execute('select count(*) from People_Inf where Name_Url=?', (people_list,))
OperationalError: unable to open database file
2016-07-15 15:07:43,941 - __main__ - DEBUG - there is a error
Traceback (most recent call last):
  File "spyder.py", line 50, in spyder
    cur2.execute('select count(*) from People_Inf where Name_Url=?', (people_list,))
OperationalError: unable to open database file
2016-07-15 15:07:44,008 - __main__ - DEBUG - there is a error
Traceback (most recent call last):
  File "spyder.py", line 50, in spyder
    cur2.execute('select count(*) from People_Inf where Name_Url=?', (people_list,))
OperationalError: unable to open database file
2016-07-15 15:07:44,076 - __main__ - DEBUG - there is a error
Traceback (most recent call last):
  File "spyder.py", line 50, in spyder
    cur2.execute('select count(*) from People_Inf where Name_Url=?', (people_list,))
OperationalError: unable to open database file
2016-07-15 15:07:44,147 - __main__ - DEBUG - there is a error
Traceback (most recent call last):
  File "spyder.py", line 50, in spyder
    cur2.execute('select count(*) from People_Inf where Name_Url=?', (people_list,))
OperationalError: unable to open database file
2016-07-15 15:07:44,221 - __main__ - DEBUG - there is a error
Traceback (most recent call last):
  File "spyder.py", line 50, in spyder
    cur2.execute('select count(*) from People_Inf where Name_Url=?', (people_list,))
OperationalError: unable to open database file
2016-07-15 15:07:44,290 - __main__ - DEBUG - there is a error
Traceback (most recent call last):
  File "spyder.py", line 50, in spyder
    cur2.execute('select count(*) from People_Inf where Name_Url=?', (people_list,))
OperationalError: unable to open database file
2016-07-15 15:07:44,360 - __main__ - DEBUG - there is a error
Traceback (most recent call last):
  File "spyder.py", line 50, in spyder
    cur2.execute('select count(*) from People_Inf where Name_Url=?', (people_list,))
OperationalError: unable to open database file
2016-07-15 15:07:44,434 - __main__ - DEBUG - there is a error
Traceback (most recent call last):
  File "spyder.py", line 50, in spyder
    cur2.execute('select count(*) from People_Inf where Name_Url=?', (people_list,))
OperationalError: unable to open database file
2016-07-15 15:07:44,511 - __main__ - DEBUG - there is a error
Traceback (most recent call last):
  File "spyder.py", line 50, in spyder
    cur2.execute('select count(*) from People_Inf where Name_Url=?', (people_list,))
OperationalError: unable to open database file
2016-07-15 15:07:44,590 - __main__ - DEBUG - there is a error
Traceback (most recent call last):
  File "spyder.py", line 50, in spyder
    cur2.execute('select count(*) from People_Inf where Name_Url=?', (people_list,))
OperationalError: unable to open database file
2016-07-15 15:07:44,661 - __main__ - DEBUG - there is a error
Traceback (most recent call last):
  File "spyder.py", line 50, in spyder
    cur2.execute('select count(*) from People_Inf where Name_Url=?', (people_list,))
OperationalError: unable to open database file
2016-07-15 15:07:44,802 - __main__ - DEBUG - there is a error
Traceback (most recent call last):
  File "spyder.py", line 50, in spyder
    cur2.execute('select count(*) from People_Inf where Name_Url=?', (people_list,))
OperationalError: unable to open database file
2016-07-15 15:07:44,890 - __main__ - DEBUG - there is a error
Traceback (most recent call last):
  File "spyder.py", line 50, in spyder
    cur2.execute('select count(*) from People_Inf where Name_Url=?', (people_list,))
OperationalError: unable to open database file
2016-07-15 15:07:45,017 - __main__ - DEBUG - there is a error
Traceback (most recent call last):
  File "spyder.py", line 50, in spyder
    cur2.execute('select count(*) from People_Inf where Name_Url=?', (people_list,))
OperationalError: unable to open database file
2016-07-15 15:07:45,086 - __main__ - DEBUG - there is a error
Traceback (most recent call last):
  File "spyder.py", line 50, in spyder
    cur2.execute('select count(*) from People_Inf where Name_Url=?', (people_list,))
OperationalError: unable to open database file
2016-07-15 15:07:45,158 - __main__ - DEBUG - there is a error
Traceback (most recent call last):
  File "spyder.py", line 50, in spyder
    cur2.execute('select count(*) from People_Inf where Name_Url=?', (people_list,))
OperationalError: unable to open database file
2016-07-15 15:07:45,227 - __main__ - DEBUG - there is a error
Traceback (most recent call last):
  File "spyder.py", line 50, in spyder
    cur2.execute('select count(*) from People_Inf where Name_Url=?', (people_list,))
OperationalError: unable to open database file
2016-07-15 15:07:45,294 - __main__ - DEBUG - there is a error
Traceback (most recent call last):
  File "spyder.py", line 50, in spyder
    cur2.execute('select count(*) from People_Inf where Name_Url=?', (people_list,))
OperationalError: unable to open database file
2016-07-15 15:07:45,363 - __main__ - DEBUG - there is a error
Traceback (most recent call last):
  File "spyder.py", line 50, in spyder
    cur2.execute('select count(*) from People_Inf where Name_Url=?', (people_list,))
OperationalError: unable to open database file
2016-07-15 15:07:45,433 - __main__ - DEBUG - there is a error
Traceback (most recent call last):
  File "spyder.py", line 50, in spyder
    cur2.execute('select count(*) from People_Inf where Name_Url=?', (people_list,))
OperationalError: unable to open database file
2016-07-15 15:07:45,506 - __main__ - DEBUG - there is a error
Traceback (most recent call last):
  File "spyder.py", line 50, in spyder
    cur2.execute('select count(*) from People_Inf where Name_Url=?', (people_list,))
OperationalError: unable to open database file
2016-07-15 15:07:45,574 - __main__ - DEBUG - there is a error
Traceback (most recent call last):
  File "spyder.py", line 50, in spyder
    cur2.execute('select count(*) from People_Inf where Name_Url=?', (people_list,))
OperationalError: unable to open database file
2016-07-15 15:07:45,656 - __main__ - DEBUG - there is a error
Traceback (most recent call last):
  File "spyder.py", line 50, in spyder
    cur2.execute('select count(*) from People_Inf where Name_Url=?', (people_list,))
OperationalError: unable to open database file
2016-07-15 15:07:45,725 - __main__ - DEBUG - there is a error
Traceback (most recent call last):
  File "spyder.py", line 50, in spyder
    cur2.execute('select count(*) from People_Inf where Name_Url=?', (people_list,))
OperationalError: unable to open database file
2016-07-15 15:07:45,799 - __main__ - DEBUG - there is a error
Traceback (most recent call last):
  File "spyder.py", line 50, in spyder
    cur2.execute('select count(*) from People_Inf where Name_Url=?', (people_list,))
OperationalError: unable to open database file
2016-07-15 15:07:45,895 - __main__ - DEBUG - there is a error
Traceback (most recent call last):
  File "spyder.py", line 50, in spyder
    cur2.execute('select count(*) from People_Inf where Name_Url=?', (people_list,))
OperationalError: unable to open database file
2016-07-15 15:07:45,967 - __main__ - DEBUG - there is a error
Traceback (most recent call last):
  File "spyder.py", line 50, in spyder
    cur2.execute('select count(*) from People_Inf where Name_Url=?', (people_list,))
OperationalError: unable to open database file
2016-07-15 15:07:46,066 - __main__ - DEBUG - there is a error
Traceback (most recent call last):
  File "spyder.py", line 50, in spyder
    cur2.execute('select count(*) from People_Inf where Name_Url=?', (people_list,))
OperationalError: unable to open database file
2016-07-15 15:07:46,147 - __main__ - DEBUG - there is a error
Traceback (most recent call last):
  File "spyder.py", line 50, in spyder
    cur2.execute('select count(*) from People_Inf where Name_Url=?', (people_list,))
OperationalError: unable to open database file
2016-07-15 15:07:46,231 - __main__ - DEBUG - there is a error
Traceback (most recent call last):
  File "spyder.py", line 50, in spyder
    cur2.execute('select count(*) from People_Inf where Name_Url=?', (people_list,))
OperationalError: unable to open database file
2016-07-15 15:07:46,300 - __main__ - DEBUG - there is a error
Traceback (most recent call last):
  File "spyder.py", line 50, in spyder
    cur2.execute('select count(*) from People_Inf where Name_Url=?', (people_list,))
OperationalError: unable to open database file
2016-07-15 15:07:46,367 - __main__ - DEBUG - there is a error
Traceback (most recent call last):
  File "spyder.py", line 50, in spyder
    cur2.execute('select count(*) from People_Inf where Name_Url=?', (people_list,))
OperationalError: unable to open database file
2016-07-15 15:07:46,434 - __main__ - DEBUG - there is a error
Traceback (most recent call last):
  File "spyder.py", line 50, in spyder
    cur2.execute('select count(*) from People_Inf where Name_Url=?', (people_list,))
OperationalError: unable to open database file
2016-07-15 15:07:46,498 - __main__ - DEBUG - there is a error
Traceback (most recent call last):
  File "spyder.py", line 50, in spyder
    cur2.execute('select count(*) from People_Inf where Name_Url=?', (people_list,))
OperationalError: unable to open database file
2016-07-15 15:07:46,565 - __main__ - DEBUG - there is a error
Traceback (most recent call last):
  File "spyder.py", line 50, in spyder
    cur2.execute('select count(*) from People_Inf where Name_Url=?', (people_list,))
OperationalError: unable to open database file
2016-07-15 15:07:46,638 - __main__ - DEBUG - there is a error
Traceback (most recent call last):
  File "spyder.py", line 50, in spyder
    cur2.execute('select count(*) from People_Inf where Name_Url=?', (people_list,))
OperationalError: unable to open database file
2016-07-15 15:07:46,703 - __main__ - DEBUG - there is a error
Traceback (most recent call last):
  File "spyder.py", line 50, in spyder
    cur2.execute('select count(*) from People_Inf where Name_Url=?', (people_list,))
OperationalError: unable to open database file
2016-07-15 15:07:46,773 - __main__ - DEBUG - there is a error
Traceback (most recent call last):
  File "spyder.py", line 50, in spyder
    cur2.execute('select count(*) from People_Inf where Name_Url=?', (people_list,))
OperationalError: unable to open database file
2016-07-15 15:07:46,839 - __main__ - DEBUG - there is a error
Traceback (most recent call last):
  File "spyder.py", line 50, in spyder
    cur2.execute('select count(*) from People_Inf where Name_Url=?', (people_list,))
OperationalError: unable to open database file
2016-07-15 15:07:46,922 - __main__ - DEBUG - there is a error
Traceback (most recent call last):
  File "spyder.py", line 50, in spyder
    cur2.execute('select count(*) from People_Inf where Name_Url=?', (people_list,))
OperationalError: unable to open database file
2016-07-15 15:07:46,989 - __main__ - DEBUG - there is a error
Traceback (most recent call last):
  File "spyder.py", line 50, in spyder
    cur2.execute('select count(*) from People_Inf where Name_Url=?', (people_list,))
OperationalError: unable to open database file
2016-07-15 15:07:47,053 - __main__ - DEBUG - there is a error
Traceback (most recent call last):
  File "spyder.py", line 50, in spyder
    cur2.execute('select count(*) from People_Inf where Name_Url=?', (people_list,))
OperationalError: unable to open database file
2016-07-15 15:07:47,121 - __main__ - DEBUG - there is a error
Traceback (most recent call last):
  File "spyder.py", line 50, in spyder
    cur2.execute('select count(*) from People_Inf where Name_Url=?', (people_list,))
OperationalError: unable to open database file
2016-07-15 15:07:47,191 - __main__ - DEBUG - there is a error
Traceback (most recent call last):
  File "spyder.py", line 50, in spyder
    cur2.execute('select count(*) from People_Inf where Name_Url=?', (people_list,))
OperationalError: unable to open database file
2016-07-15 15:07:47,258 - __main__ - DEBUG - there is a error
Traceback (most recent call last):
  File "spyder.py", line 50, in spyder
    cur2.execute('select count(*) from People_Inf where Name_Url=?', (people_list,))
OperationalError: unable to open database file
2016-07-15 15:07:47,341 - __main__ - DEBUG - there is a error
Traceback (most recent call last):
  File "spyder.py", line 50, in spyder
    cur2.execute('select count(*) from People_Inf where Name_Url=?', (people_list,))
OperationalError: unable to open database file
2016-07-15 15:07:47,423 - __main__ - DEBUG - there is a error
Traceback (most recent call last):
  File "spyder.py", line 50, in spyder
    cur2.execute('select count(*) from People_Inf where Name_Url=?', (people_list,))
OperationalError: unable to open database file
2016-07-15 15:07:47,492 - __main__ - DEBUG - there is a error
Traceback (most recent call last):
  File "spyder.py", line 50, in spyder
    cur2.execute('select count(*) from People_Inf where Name_Url=?', (people_list,))
OperationalError: unable to open database file
2016-07-15 15:07:47,559 - __main__ - DEBUG - there is a error
Traceback (most recent call last):
  File "spyder.py", line 50, in spyder
    cur2.execute('select count(*) from People_Inf where Name_Url=?', (people_list,))
OperationalError: unable to open database file
2016-07-15 15:07:47,627 - __main__ - DEBUG - there is a error
Traceback (most recent call last):
  File "spyder.py", line 50, in spyder
    cur2.execute('select count(*) from People_Inf where Name_Url=?', (people_list,))
OperationalError: unable to open database file
2016-07-15 15:07:47,693 - __main__ - DEBUG - there is a error
Traceback (most recent call last):
  File "spyder.py", line 50, in spyder
    cur2.execute('select count(*) from People_Inf where Name_Url=?', (people_list,))
OperationalError: unable to open database file
2016-07-15 15:07:47,759 - __main__ - DEBUG - there is a error
Traceback (most recent call last):
  File "spyder.py", line 50, in spyder
    cur2.execute('select count(*) from People_Inf where Name_Url=?', (people_list,))
OperationalError: unable to open database file
2016-07-15 15:07:47,825 - __main__ - DEBUG - there is a error
Traceback (most recent call last):
  File "spyder.py", line 50, in spyder
    cur2.execute('select count(*) from People_Inf where Name_Url=?', (people_list,))
OperationalError: unable to open database file
2016-07-15 15:07:47,891 - __main__ - DEBUG - there is a error
Traceback (most recent call last):
  File "spyder.py", line 50, in spyder
    cur2.execute('select count(*) from People_Inf where Name_Url=?', (people_list,))
OperationalError: unable to open database file
2016-07-15 15:07:47,961 - __main__ - DEBUG - there is a error
Traceback (most recent call last):
  File "spyder.py", line 50, in spyder
    cur2.execute('select count(*) from People_Inf where Name_Url=?', (people_list,))
OperationalError: unable to open database file
2016-07-15 15:07:48,027 - __main__ - DEBUG - there is a error
Traceback (most recent call last):
  File "spyder.py", line 50, in spyder
    cur2.execute('select count(*) from People_Inf where Name_Url=?', (people_list,))
OperationalError: unable to open database file
2016-07-15 15:07:48,092 - __main__ - DEBUG - there is a error
Traceback (most recent call last):
  File "spyder.py", line 50, in spyder
    cur2.execute('select count(*) from People_Inf where Name_Url=?', (people_list,))
OperationalError: unable to open database file
2016-07-15 15:07:48,158 - __main__ - DEBUG - there is a error
Traceback (most recent call last):
  File "spyder.py", line 50, in spyder
    cur2.execute('select count(*) from People_Inf where Name_Url=?', (people_list,))
OperationalError: unable to open database file
2016-07-15 15:07:48,226 - __main__ - DEBUG - there is a error
Traceback (most recent call last):
  File "spyder.py", line 50, in spyder
    cur2.execute('select count(*) from People_Inf where Name_Url=?', (people_list,))
OperationalError: unable to open database file
2016-07-15 15:07:48,297 - __main__ - DEBUG - there is a error
Traceback (most recent call last):
  File "spyder.py", line 50, in spyder
    cur2.execute('select count(*) from People_Inf where Name_Url=?', (people_list,))
OperationalError: unable to open database file
2016-07-15 15:07:48,363 - __main__ - DEBUG - there is a error
Traceback (most recent call last):
  File "spyder.py", line 50, in spyder
    cur2.execute('select count(*) from People_Inf where Name_Url=?', (people_list,))
OperationalError: unable to open database file
2016-07-15 15:07:48,429 - __main__ - DEBUG - there is a error
Traceback (most recent call last):
  File "spyder.py", line 50, in spyder
    cur2.execute('select count(*) from People_Inf where Name_Url=?', (people_list,))
OperationalError: unable to open database file
2016-07-15 15:07:48,496 - __main__ - DEBUG - there is a error
Traceback (most recent call last):
  File "spyder.py", line 50, in spyder
    cur2.execute('select count(*) from People_Inf where Name_Url=?', (people_list,))
OperationalError: unable to open database file
2016-07-15 15:07:48,575 - __main__ - DEBUG - there is a error
Traceback (most recent call last):
  File "spyder.py", line 50, in spyder
    cur2.execute('select count(*) from People_Inf where Name_Url=?', (people_list,))
OperationalError: unable to open database file
2016-07-15 15:07:48,642 - __main__ - DEBUG - there is a error
Traceback (most recent call last):
  File "spyder.py", line 50, in spyder
    cur2.execute('select count(*) from People_Inf where Name_Url=?', (people_list,))
OperationalError: unable to open database file
2016-07-15 15:07:48,716 - __main__ - DEBUG - there is a error
Traceback (most recent call last):
  File "spyder.py", line 50, in spyder
    cur2.execute('select count(*) from People_Inf where Name_Url=?', (people_list,))
OperationalError: unable to open database file
2016-07-15 15:07:48,788 - __main__ - DEBUG - there is a error
Traceback (most recent call last):
  File "spyder.py", line 50, in spyder
    cur2.execute('select count(*) from People_Inf where Name_Url=?', (people_list,))
OperationalError: unable to open database file
2016-07-15 15:07:48,854 - __main__ - DEBUG - there is a error
Traceback (most recent call last):
  File "spyder.py", line 50, in spyder
    cur2.execute('select count(*) from People_Inf where Name_Url=?', (people_list,))
OperationalError: unable to open database file
2016-07-15 15:07:48,921 - __main__ - DEBUG - there is a error
Traceback (most recent call last):
  File "spyder.py", line 50, in spyder
    cur2.execute('select count(*) from People_Inf where Name_Url=?', (people_list,))
OperationalError: unable to open database file
2016-07-15 15:07:48,987 - __main__ - DEBUG - there is a error
Traceback (most recent call last):
  File "spyder.py", line 50, in spyder
    cur2.execute('select count(*) from People_Inf where Name_Url=?', (people_list,))
OperationalError: unable to open database file
2016-07-15 15:07:49,074 - __main__ - DEBUG - there is a error
Traceback (most recent call last):
  File "spyder.py", line 50, in spyder
    cur2.execute('select count(*) from People_Inf where Name_Url=?', (people_list,))
OperationalError: unable to open database file
2016-07-15 15:07:49,141 - __main__ - DEBUG - there is a error
Traceback (most recent call last):
  File "spyder.py", line 50, in spyder
    cur2.execute('select count(*) from People_Inf where Name_Url=?', (people_list,))
OperationalError: unable to open database file
2016-07-15 15:07:49,210 - __main__ - DEBUG - there is a error
Traceback (most recent call last):
  File "spyder.py", line 50, in spyder
    cur2.execute('select count(*) from People_Inf where Name_Url=?', (people_list,))
OperationalError: unable to open database file
2016-07-15 15:07:49,277 - __main__ - DEBUG - there is a error
Traceback (most recent call last):
  File "spyder.py", line 50, in spyder
    cur2.execute('select count(*) from People_Inf where Name_Url=?', (people_list,))
OperationalError: unable to open database file
2016-07-15 15:07:49,345 - __main__ - DEBUG - there is a error
Traceback (most recent call last):
  File "spyder.py", line 50, in spyder
    cur2.execute('select count(*) from People_Inf where Name_Url=?', (people_list,))
OperationalError: unable to open database file
2016-07-15 15:07:49,412 - __main__ - DEBUG - there is a error
Traceback (most recent call last):
  File "spyder.py", line 50, in spyder
    cur2.execute('select count(*) from People_Inf where Name_Url=?', (people_list,))
OperationalError: unable to open database file
2016-07-15 15:07:49,485 - __main__ - DEBUG - there is a error
Traceback (most recent call last):
  File "spyder.py", line 50, in spyder
    cur2.execute('select count(*) from People_Inf where Name_Url=?', (people_list,))
OperationalError: unable to open database file
2016-07-15 15:07:49,551 - __main__ - DEBUG - there is a error
Traceback (most recent call last):
  File "spyder.py", line 50, in spyder
    cur2.execute('select count(*) from People_Inf where Name_Url=?', (people_list,))
OperationalError: unable to open database file
2016-07-15 15:07:49,643 - __main__ - DEBUG - there is a error
Traceback (most recent call last):
  File "spyder.py", line 50, in spyder
    cur2.execute('select count(*) from People_Inf where Name_Url=?', (people_list,))
OperationalError: unable to open database file
2016-07-15 15:07:49,710 - __main__ - DEBUG - there is a error
Traceback (most recent call last):
  File "spyder.py", line 50, in spyder
    cur2.execute('select count(*) from People_Inf where Name_Url=?', (people_list,))
OperationalError: unable to open database file
2016-07-15 15:07:49,777 - __main__ - DEBUG - there is a error
Traceback (most recent call last):
  File "spyder.py", line 50, in spyder
    cur2.execute('select count(*) from People_Inf where Name_Url=?', (people_list,))
OperationalError: unable to open database file
2016-07-15 15:07:49,845 - __main__ - DEBUG - there is a error
Traceback (most recent call last):
  File "spyder.py", line 50, in spyder
    cur2.execute('select count(*) from People_Inf where Name_Url=?', (people_list,))
OperationalError: unable to open database file
2016-07-15 15:07:49,915 - __main__ - DEBUG - there is a error
Traceback (most recent call last):
  File "spyder.py", line 50, in spyder
    cur2.execute('select count(*) from People_Inf where Name_Url=?', (people_list,))
OperationalError: unable to open database file
2016-07-15 15:07:49,984 - __main__ - DEBUG - there is a error
Traceback (most recent call last):
  File "spyder.py", line 50, in spyder
    cur2.execute('select count(*) from People_Inf where Name_Url=?', (people_list,))
OperationalError: unable to open database file
2016-07-15 15:07:50,270 - __main__ - DEBUG - there is a error
Traceback (most recent call last):
  File "spyder.py", line 50, in spyder
    cur2.execute('select count(*) from People_Inf where Name_Url=?', (people_list,))
OperationalError: unable to open database file
2016-07-15 15:07:50,743 - __main__ - DEBUG - there is a error
Traceback (most recent call last):
  File "spyder.py", line 50, in spyder
    cur2.execute('select count(*) from People_Inf where Name_Url=?', (people_list,))
OperationalError: unable to open database file
2016-07-15 15:07:50,818 - __main__ - DEBUG - there is a error
Traceback (most recent call last):
  File "spyder.py", line 50, in spyder
    cur2.execute('select count(*) from People_Inf where Name_Url=?', (people_list,))
OperationalError: unable to open database file
2016-07-15 15:07:50,893 - __main__ - DEBUG - there is a error
Traceback (most recent call last):
  File "spyder.py", line 50, in spyder
    cur2.execute('select count(*) from People_Inf where Name_Url=?', (people_list,))
OperationalError: unable to open database file
2016-07-15 15:07:50,965 - __main__ - DEBUG - there is a error
Traceback (most recent call last):
  File "spyder.py", line 50, in spyder
    cur2.execute('select count(*) from People_Inf where Name_Url=?', (people_list,))
OperationalError: unable to open database file
2016-07-15 15:07:51,031 - __main__ - DEBUG - there is a error
Traceback (most recent call last):
  File "spyder.py", line 50, in spyder
    cur2.execute('select count(*) from People_Inf where Name_Url=?', (people_list,))
OperationalError: unable to open database file
2016-07-15 15:07:51,102 - __main__ - DEBUG - there is a error
Traceback (most recent call last):
  File "spyder.py", line 50, in spyder
    cur2.execute('select count(*) from People_Inf where Name_Url=?', (people_list,))
OperationalError: unable to open database file
2016-07-15 15:07:51,169 - __main__ - DEBUG - there is a error
Traceback (most recent call last):
  File "spyder.py", line 50, in spyder
    cur2.execute('select count(*) from People_Inf where Name_Url=?', (people_list,))
OperationalError: unable to open database file
2016-07-15 15:07:51,237 - __main__ - DEBUG - there is a error
Traceback (most recent call last):
  File "spyder.py", line 50, in spyder
    cur2.execute('select count(*) from People_Inf where Name_Url=?', (people_list,))
OperationalError: unable to open database file
2016-07-15 15:07:51,304 - __main__ - DEBUG - there is a error
Traceback (most recent call last):
  File "spyder.py", line 50, in spyder
    cur2.execute('select count(*) from People_Inf where Name_Url=?', (people_list,))
OperationalError: unable to open database file
2016-07-15 15:07:51,370 - __main__ - DEBUG - there is a error
Traceback (most recent call last):
  File "spyder.py", line 50, in spyder
    cur2.execute('select count(*) from People_Inf where Name_Url=?', (people_list,))
OperationalError: unable to open database file
2016-07-15 15:07:51,439 - __main__ - DEBUG - there is a error
Traceback (most recent call last):
  File "spyder.py", line 50, in spyder
    cur2.execute('select count(*) from People_Inf where Name_Url=?', (people_list,))
OperationalError: unable to open database file
2016-07-15 15:07:51,507 - __main__ - DEBUG - there is a error
Traceback (most recent call last):
  File "spyder.py", line 50, in spyder
    cur2.execute('select count(*) from People_Inf where Name_Url=?', (people_list,))
OperationalError: unable to open database file
2016-07-15 15:07:51,573 - __main__ - DEBUG - there is a error
Traceback (most recent call last):
  File "spyder.py", line 50, in spyder
    cur2.execute('select count(*) from People_Inf where Name_Url=?', (people_list,))
OperationalError: unable to open database file
2016-07-15 15:07:51,640 - __main__ - DEBUG - there is a error
Traceback (most recent call last):
  File "spyder.py", line 50, in spyder
    cur2.execute('select count(*) from People_Inf where Name_Url=?', (people_list,))
OperationalError: unable to open database file
2016-07-15 15:07:51,706 - __main__ - DEBUG - there is a error
Traceback (most recent call last):
  File "spyder.py", line 50, in spyder
    cur2.execute('select count(*) from People_Inf where Name_Url=?', (people_list,))
OperationalError: unable to open database file
2016-07-15 15:07:51,787 - __main__ - DEBUG - there is a error
Traceback (most recent call last):
  File "spyder.py", line 50, in spyder
    cur2.execute('select count(*) from People_Inf where Name_Url=?', (people_list,))
OperationalError: unable to open database file
2016-07-15 15:07:51,864 - __main__ - DEBUG - there is a error
Traceback (most recent call last):
  File "spyder.py", line 50, in spyder
    cur2.execute('select count(*) from People_Inf where Name_Url=?', (people_list,))
OperationalError: unable to open database file
2016-07-15 15:07:51,936 - __main__ - DEBUG - there is a error
Traceback (most recent call last):
  File "spyder.py", line 50, in spyder
    cur2.execute('select count(*) from People_Inf where Name_Url=?', (people_list,))
OperationalError: unable to open database file
2016-07-15 15:07:52,001 - __main__ - DEBUG - there is a error
Traceback (most recent call last):
  File "spyder.py", line 50, in spyder
    cur2.execute('select count(*) from People_Inf where Name_Url=?', (people_list,))
OperationalError: unable to open database file
2016-07-15 15:07:52,067 - __main__ - DEBUG - there is a error
Traceback (most recent call last):
  File "spyder.py", line 50, in spyder
    cur2.execute('select count(*) from People_Inf where Name_Url=?', (people_list,))
OperationalError: unable to open database file
2016-07-15 15:07:52,137 - __main__ - DEBUG - there is a error
Traceback (most recent call last):
  File "spyder.py", line 50, in spyder
    cur2.execute('select count(*) from People_Inf where Name_Url=?', (people_list,))
OperationalError: unable to open database file
2016-07-15 15:07:52,242 - __main__ - DEBUG - there is a error
Traceback (most recent call last):
  File "spyder.py", line 50, in spyder
    cur2.execute('select count(*) from People_Inf where Name_Url=?', (people_list,))
OperationalError: unable to open database file
2016-07-15 15:07:52,330 - __main__ - DEBUG - there is a error
Traceback (most recent call last):
  File "spyder.py", line 50, in spyder
    cur2.execute('select count(*) from People_Inf where Name_Url=?', (people_list,))
OperationalError: unable to open database file
2016-07-15 15:07:52,422 - __main__ - DEBUG - there is a error
Traceback (most recent call last):
  File "spyder.py", line 50, in spyder
    cur2.execute('select count(*) from People_Inf where Name_Url=?', (people_list,))
OperationalError: unable to open database file
2016-07-15 15:07:52,488 - __main__ - DEBUG - there is a error
Traceback (most recent call last):
  File "spyder.py", line 50, in spyder
    cur2.execute('select count(*) from People_Inf where Name_Url=?', (people_list,))
OperationalError: unable to open database file
2016-07-15 15:07:52,554 - __main__ - DEBUG - there is a error
Traceback (most recent call last):
  File "spyder.py", line 50, in spyder
    cur2.execute('select count(*) from People_Inf where Name_Url=?', (people_list,))
OperationalError: unable to open database file
2016-07-15 15:07:52,636 - __main__ - DEBUG - there is a error
Traceback (most recent call last):
  File "spyder.py", line 50, in spyder
    cur2.execute('select count(*) from People_Inf where Name_Url=?', (people_list,))
OperationalError: unable to open database file
2016-07-15 15:07:52,708 - __main__ - DEBUG - there is a error
Traceback (most recent call last):
  File "spyder.py", line 50, in spyder
    cur2.execute('select count(*) from People_Inf where Name_Url=?', (people_list,))
OperationalError: unable to open database file
2016-07-15 15:07:52,782 - __main__ - DEBUG - there is a error
Traceback (most recent call last):
  File "spyder.py", line 50, in spyder
    cur2.execute('select count(*) from People_Inf where Name_Url=?', (people_list,))
OperationalError: unable to open database file
2016-07-15 15:07:52,866 - __main__ - DEBUG - there is a error
Traceback (most recent call last):
  File "spyder.py", line 50, in spyder
    cur2.execute('select count(*) from People_Inf where Name_Url=?', (people_list,))
OperationalError: unable to open database file
2016-07-15 15:07:52,938 - __main__ - DEBUG - there is a error
Traceback (most recent call last):
  File "spyder.py", line 50, in spyder
    cur2.execute('select count(*) from People_Inf where Name_Url=?', (people_list,))
OperationalError: unable to open database file
2016-07-15 15:07:53,084 - __main__ - DEBUG - there is a error
Traceback (most recent call last):
  File "spyder.py", line 50, in spyder
    cur2.execute('select count(*) from People_Inf where Name_Url=?', (people_list,))
OperationalError: unable to open database file
